Workbook
Name CAP: 'لوحة التحكم'!$C$8
Name HTYPE: 'لوحة التحكم'!$C$7
Name RMODE: 'لوحة التحكم'!$C$9
Name MOBILEBEDS: 'لوحة التحكم'!$C$10

Sheet دليل الاستخدام
A1: دليل استخدام نموذج حساب معايير القوى العاملة
A2: المصدر: المعايير القياسية للقوى العاملة بمستشفيات وزارة الصحة — النسخة الثانية 2023م — وكالة الوزارة للخدمات العلاجية / الإدارة العامة لشؤون المستشفيات
A5: كيف يعمل النموذج؟
A6: 1 | B6: افتح ورقة «لوحة التحكم» وأدخل: اسم المستشفى، نوع المستشفى، والسعة السريرية (عدد الأسرة).
A7: 2 | B7: تُحتسب أعمدة «الاحتياج للسعة المدخلة» في كل ورقة معيار تلقائياً بمجرد إدخال السعة السريرية.
A8: 3 | B8: أدخل الأعداد الحالية للموظفين في عمود «الموجود فعلياً» (الخلايا الصفراء) في أوراق المعايير.
A9: 4 | B9: تظهر الفجوة ونسبة التغطية والحالة تلقائياً لكل مسمى وظيفي، ويتجمّع الملخص في «لوحة التحكم».
A11: قواعد الحساب
A12: الشرائح المعيارية | B12: الدليل يحدد الأعداد عند سعات محددة (50 / 100 / 150 / 200 / 300 / 400 / 500 سرير للمستشفيات العامة).
A13: السعات غير المذكورة | B13: يُستخدم الاستيفاء الخطي (Linear Interpolation) بين أقرب شريحتين. مثال: سعة 250 سرير = القيمة عند 200 + نصف الفرق بين 200 و 300.
A14: أقل من أصغر شريحة | B14: يُحسب تناسبياً من أصغر شريحة (القيمة × السعة ÷ أصغر شريحة).
A15: أكبر من أكبر شريحة | B15: يُحسب تناسبياً من أكبر شريحة (القيمة × السعة ÷ أكبر شريحة).
A16: التقريب | B16: افتراضياً «تقريب لأعلى» لأن الدليل يمثل الحد الأدنى للقوى العاملة. يمكن تغييره من لوحة التحكم إلى «تقريب لأقرب صحيح».
A17: عند السعات المعيارية | B17: تُطابق نتائج النموذج أرقام الدليل حرفياً (تم التحقق من كل جدول مقابل المجاميع المنشورة).
A19: دلالة الألوان
A20: أصفر / خط أزرق | B20: خلايا إدخال — أنت من يعبّئها.
A21: أخضر فاتح | B21: خلايا محسوبة تلقائياً — لا تُعدَّل.
A22: أزرق فاتح | B22: قيم المعيار كما وردت في الدليل — مرجعية ثابتة.
A23: رمادي | B23: صفوف مقارنة/تدقيق.
A25: تنبيهات مهنية
A26: الحد الأدنى | B26: المعيار يمثل الحد الأدنى للقوى العاملة وليس العدد الأمثل (إيضاح 1).
A27: نطاق الخدمة | B27: لا يُطبَّق معيار أي تخصص ما لم تتوفر خدمته فعلياً في المنشأة (إيضاح 42) — راجع ورقة «نطاق الخدمات».
A28: العنايات المركزة | B28: يُطبَّق معيار العنايات المركزة فقط إذا كانت المستشفى تقدم الخدمة ومعتمدة (إيضاح 8).
A29: الأقسام المشروطة | B29: الأورام، زراعة القوقعة، العقم، جراحة السمنة، التأهيل الطبي — تُطبَّق عند اعتماد المركز فقط (إيضاحات 34، 37-41).
A30: راجع الإيضاحات | B30: ورقة «الإيضاحات» تحتوي الإيضاحات الـ 42 الواردة في الدليل كاملة.

Sheet لوحة التحكم
A1: لوحة التحكم — حساب الاحتياج من القوى العاملة
A2: المصدر: المعايير القياسية للقوى العاملة بمستشفيات وزارة الصحة — النسخة الثانية 2023م — وكالة الوزارة للخدمات العلاجية / الإدارة العامة لشؤون المستشفيات
B4: ① بيانات المستشفى — عبّئ الخلايا الصفراء
B5: اسم المستشفى | C5: مستشفى الملك فهد العام (مثال — استبدله)
B6: المنطقة / التجمع الصحي | C6: تجمع ... الصحي (مثال — استبدله)
B7: نوع المستشفى | C7: مستشفى عام | E7: ◄ اختر من القائمة
B8: السعة السريرية (عدد الأسرة) | C8: 250 | E8: ◄ أي رقم؛ يُستوفى خطياً بين شرائح الدليل
B9: طريقة التقريب | C9: تقريب لأعلى | E9: ◄ الدليل حد أدنى ⇒ الافتراضي: تقريب لأعلى
B10: اعتماد الأسرة المتحركة | C10: لا | E10: ◄ إيضاحات 26-29: تؤثر على نسبة التمريض لكل سرير
B11: تاريخ التقييم | C11: 1447/01/01هـ
B13: ② ملخص الاحتياج والفجوة (يُحدَّث تلقائياً)
B14: الفئة | C14: الاحتياج حسب المعيار | D14: الموجود فعلياً | E14: الفجوة (+فائض / -عجز) | F14: نسبة التغطية | G14: المعدل لكل سرير | H14: الحالة
B15: الأطباء | C15: =INDEX('مصفوفة الحساب'!$B$4:$E$11,MATCH($I15,'مصفوفة الحساب'!$A$4:$A$11,0),MATCH(HTYPE,'مصفوفة الحساب'!$B$2:$E$2,0)) | D15: =INDEX('مصفوفة الحساب'!$F$4:$I$11,MATCH($I15,'مصفوفة الحساب'!$A$4:$A$11,0),MATCH(HTYPE,'مصفوفة الحساب'!$F$2:$I$2,0)) | E15: =D15-C15 | F15: =IF(C15=0,"",D15/C15) | G15: =IF(CAP=0,"",C15/CAP) | H15: =IF(C15=0,"لا ينطبق",IF(D15>=C15,"مكتمل",IF(D15=0,"لم يُدخل","عجز"))) | I15: طبيب
B16: التمريض | C16: =INDEX('مصفوفة الحساب'!$B$4:$E$11,MATCH($I16,'مصفوفة الحساب'!$A$4:$A$11,0),MATCH(HTYPE,'مصفوفة الحساب'!$B$2:$E$2,0)) | D16: =INDEX('مصفوفة الحساب'!$F$4:$I$11,MATCH($I16,'مصفوفة الحساب'!$A$4:$A$11,0),MATCH(HTYPE,'مصفوفة الحساب'!$F$2:$I$2,0)) | E16: =D16-C16 | F16: =IF(C16=0,"",D16/C16) | G16: =IF(CAP=0,"",C16/CAP) | H16: =IF(C16=0,"لا ينطبق",IF(D16>=C16,"مكتمل",IF(D16=0,"لم يُدخل","عجز"))) | I16: تمريض
B17: القبالة | C17: =INDEX('مصفوفة الحساب'!$B$4:$E$11,MATCH($I17,'مصفوفة الحساب'!$A$4:$A$11,0),MATCH(HTYPE,'مصفوفة الحساب'!$B$2:$E$2,0)) | D17: =INDEX('مصفوفة الحساب'!$F$4:$I$11,MATCH($I17,'مصفوفة الحساب'!$A$4:$A$11,0),MATCH(HTYPE,'مصفوفة الحساب'!$F$2:$I$2,0)) | E17: =D17-C17 | F17: =IF(C17=0,"",D17/C17) | G17: =IF(CAP=0,"",C17/CAP) | H17: =IF(C17=0,"لا ينطبق",IF(D17>=C17,"مكتمل",IF(D17=0,"لم يُدخل","عجز"))) | I17: قبالة
B18: أخصائي غير طبيب (بدون تمريض وقبالة) | C18: =INDEX('مصفوفة الحساب'!$B$4:$E$11,MATCH($I18,'مصفوفة الحساب'!$A$4:$A$11,0),MATCH(HTYPE,'مصفوفة الحساب'!$B$2:$E$2,0)) | D18: =INDEX('مصفوفة الحساب'!$F$4:$I$11,MATCH($I18,'مصفوفة الحساب'!$A$4:$A$11,0),MATCH(HTYPE,'مصفوفة الحساب'!$F$2:$I$2,0)) | E18: =D18-C18 | F18: =IF(C18=0,"",D18/C18) | G18: =IF(CAP=0,"",C18/CAP) | H18: =IF(C18=0,"لا ينطبق",IF(D18>=C18,"مكتمل",IF(D18=0,"لم يُدخل","عجز"))) | I18: أخصائي غير طبيب
B19: الفنيون (بدون تمريض وقبالة) | C19: =INDEX('مصفوفة الحساب'!$B$4:$E$11,MATCH($I19,'مصفوفة الحساب'!$A$4:$A$11,0),MATCH(HTYPE,'مصفوفة الحساب'!$B$2:$E$2,0)) | D19: =INDEX('مصفوفة الحساب'!$F$4:$I$11,MATCH($I19,'مصفوفة الحساب'!$A$4:$A$11,0),MATCH(HTYPE,'مصفوفة الحساب'!$F$2:$I$2,0)) | E19: =D19-C19 | F19: =IF(C19=0,"",D19/C19) | G19: =IF(CAP=0,"",C19/CAP) | H19: =IF(C19=0,"لا ينطبق",IF(D19>=C19,"مكتمل",IF(D19=0,"لم يُدخل","عجز"))) | I19: فني
B20: الصيادلة | C20: =INDEX('مصفوفة الحساب'!$B$4:$E$11,MATCH($I20,'مصفوفة الحساب'!$A$4:$A$11,0),MATCH(HTYPE,'مصفوفة الحساب'!$B$2:$E$2,0)) | D20: =INDEX('مصفوفة الحساب'!$F$4:$I$11,MATCH($I20,'مصفوفة الحساب'!$A$4:$A$11,0),MATCH(HTYPE,'مصفوفة الحساب'!$F$2:$I$2,0)) | E20: =D20-C20 | F20: =IF(C20=0,"",D20/C20) | G20: =IF(CAP=0,"",C20/CAP) | H20: =IF(C20=0,"لا ينطبق",IF(D20>=C20,"مكتمل",IF(D20=0,"لم يُدخل","عجز"))) | I20: صيدلي
B21: المساعد الصحي | C21: =INDEX('مصفوفة الحساب'!$B$4:$E$11,MATCH($I21,'مصفوفة الحساب'!$A$4:$A$11,0),MATCH(HTYPE,'مصفوفة الحساب'!$B$2:$E$2,0)) | D21: =INDEX('مصفوفة الحساب'!$F$4:$I$11,MATCH($I21,'مصفوفة الحساب'!$A$4:$A$11,0),MATCH(HTYPE,'مصفوفة الحساب'!$F$2:$I$2,0)) | E21: =D21-C21 | F21: =IF(C21=0,"",D21/C21) | G21: =IF(CAP=0,"",C21/CAP) | H21: =IF(C21=0,"لا ينطبق",IF(D21>=C21,"مكتمل",IF(D21=0,"لم يُدخل","عجز"))) | I21: مساعد صحي
B22: الإداريون | C22: =INDEX('مصفوفة الحساب'!$B$4:$E$11,MATCH($I22,'مصفوفة الحساب'!$A$4:$A$11,0),MATCH(HTYPE,'مصفوفة الحساب'!$B$2:$E$2,0)) | D22: =INDEX('مصفوفة الحساب'!$F$4:$I$11,MATCH($I22,'مصفوفة الحساب'!$A$4:$A$11,0),MATCH(HTYPE,'مصفوفة الحساب'!$F$2:$I$2,0)) | E22: =D22-C22 | F22: =IF(C22=0,"",D22/C22) | G22: =IF(CAP=0,"",C22/CAP) | H22: =IF(C22=0,"لا ينطبق",IF(D22>=C22,"مكتمل",IF(D22=0,"لم يُدخل","عجز"))) | I22: إداري
B23: إجمالي القوى العاملة | C23: =SUM(C15:C22) | D23: =SUM(D15:D22) | E23: =D23-C23 | F23: =IF(C23=0,"",D23/C23) | G23: =IF(CAP=0,"",C23/CAP)
B25: الاحتياج يُحتسب آلياً من أوراق المعايير حسب السعة السريرية المدخلة · «الموجود فعلياً» يُجمَّع من الخلايا الصفراء التي تعبّئها في أوراق المعايير · المعدل لكل سرير = الاحتياج ÷ السعة.

Sheet عام - الأطباء
A1: عام - الأطباء
A2: الملحق (1) — تفاصيل المعيار المحدث لفئة الأطباء (صفحات 22-25)
C3: معاملا الاستيفاء ◄ | D3: =IFERROR(MATCH(CAP,$D$4:$J$4,1),1) | E3: =IF(OR(CAP<=$D$4,CAP>=$J$4),0,(CAP-INDEX($D$4:$J$4,$D$3))/(INDEX($D$4:$J$4,$D$3+1)-INDEX($D$4:$J$4,$D$3)))
A4: م | B4: الفئة | C4: المسمى الوظيفي | D4: 50 | E4: 100 | F4: 150 | G4: 200 | H4: 300 | I4: 400 | J4: 500 | K4: الاحتياج للسعة المدخلة | L4: الموجود فعلياً | M4: الفجوة (+فائض / -عجز) | N4: نسبة التغطية | O4: الحالة | P4: القيمة قبل التقريب | Q4: ملاحظات
A5: 1 | B5: طبيب | C5: استشاري باطنة | D5: 2 | E5: 3 | F5: 3 | G5: 3 | H5: 4 | I5: 4 | J5: 8 | K5: =IF(RMODE="تقريب لأعلى",ROUNDUP(P5,0),ROUND(P5,0)) | M5: =L5-K5 | N5: =IF(K5=0,"",L5/K5) | O5: =IF(K5=0,"لا ينطبق",IF(L5>=K5,"مكتمل",IF(L5=0,"لا يوجد","عجز"))) | P5: =IF(CAP<=$D$4,D5*CAP/$D$4,IF(CAP>=$J$4,J5*CAP/$J$4,INDEX($D5:$J5,$D$3)+$E$3*(INDEX($D5:$J5,$D$3+1)-INDEX($D5:$J5,$D$3))))
A6: 2 | B6: طبيب | C6: أخصائي باطنة | D6: 3 | E6: 4 | F6: 4 | G6: 6 | H6: 8 | I6: 8 | J6: 10 | K6: =IF(RMODE="تقريب لأعلى",ROUNDUP(P6,0),ROUND(P6,0)) | M6: =L6-K6 | N6: =IF(K6=0,"",L6/K6) | O6: =IF(K6=0,"لا ينطبق",IF(L6>=K6,"مكتمل",IF(L6=0,"لا يوجد","عجز"))) | P6: =IF(CAP<=$D$4,D6*CAP/$D$4,IF(CAP>=$J$4,J6*CAP/$J$4,INDEX($D6:$J6,$D$3)+$E$3*(INDEX($D6:$J6,$D$3+1)-INDEX($D6:$J6,$D$3))))
A7: 3 | B7: طبيب | C7: مقيم باطنة | D7: 4 | E7: 3 | F7: 4 | G7: 5 | H7: 8 | I7: 10 | J7: 12 | K7: =IF(RMODE="تقريب لأعلى",ROUNDUP(P7,0),ROUND(P7,0)) | M7: =L7-K7 | N7: =IF(K7=0,"",L7/K7) | O7: =IF(K7=0,"لا ينطبق",IF(L7>=K7,"مكتمل",IF(L7=0,"لا يوجد","عجز"))) | P7: =IF(CAP<=$D$4,D7*CAP/$D$4,IF(CAP>=$J$4,J7*CAP/$J$4,INDEX($D7:$J7,$D$3)+$E$3*(INDEX($D7:$J7,$D$3+1)-INDEX($D7:$J7,$D$3))))
A8: 4 | B8: طبيب | C8: مقيم رعاية منزلية | D8: 5 | E8: 10 | F8: 15 | G8: 20 | H8: 30 | I8: 40 | J8: 50 | K8: =IF(RMODE="تقريب لأعلى",ROUNDUP(P8,0),ROUND(P8,0)) | M8: =L8-K8 | N8: =IF(K8=0,"",L8/K8) | O8: =IF(K8=0,"لا ينطبق",IF(L8>=K8,"مكتمل",IF(L8=0,"لا يوجد","عجز"))) | P8: =IF(CAP<=$D$4,D8*CAP/$D$4,IF(CAP>=$J$4,J8*CAP/$J$4,INDEX($D8:$J8,$D$3)+$E$3*(INDEX($D8:$J8,$D$3+1)-INDEX($D8:$J8,$D$3))))
A9: 5 | B9: طبيب | C9: استشاري قلب | D9: 0 | E9: 1 | F9: 1 | G9: 2 | H9: 3 | I9: 3 | J9: 4 | K9: =IF(RMODE="تقريب لأعلى",ROUNDUP(P9,0),ROUND(P9,0)) | M9: =L9-K9 | N9: =IF(K9=0,"",L9/K9) | O9: =IF(K9=0,"لا ينطبق",IF(L9>=K9,"مكتمل",IF(L9=0,"لا يوجد","عجز"))) | P9: =IF(CAP<=$D$4,D9*CAP/$D$4,IF(CAP>=$J$4,J9*CAP/$J$4,INDEX($D9:$J9,$D$3)+$E$3*(INDEX($D9:$J9,$D$3+1)-INDEX($D9:$J9,$D$3))))
A10: 6 | B10: طبيب | C10: أخصائي قلب | D10: 0 | E10: 1 | F10: 2 | G10: 2 | H10: 3 | I10: 3 | J10: 3 | K10: =IF(RMODE="تقريب لأعلى",ROUNDUP(P10,0),ROUND(P10,0)) | M10: =L10-K10 | N10: =IF(K10=0,"",L10/K10) | O10: =IF(K10=0,"لا ينطبق",IF(L10>=K10,"مكتمل",IF(L10=0,"لا يوجد","عجز"))) | P10: =IF(CAP<=$D$4,D10*CAP/$D$4,IF(CAP>=$J$4,J10*CAP/$J$4,INDEX($D10:$J10,$D$3)+$E$3*(INDEX($D10:$J10,$D$3+1)-INDEX($D10:$J10,$D$3))))
A11: 7 | B11: طبيب | C11: مقيم قلب | D11: 0 | E11: 0 | F11: 0 | G11: 0 | H11: 2 | I11: 3 | J11: 4 | K11: =IF(RMODE="تقريب لأعلى",ROUNDUP(P11,0),ROUND(P11,0)) | M11: =L11-K11 | N11: =IF(K11=0,"",L11/K11) | O11: =IF(K11=0,"لا ينطبق",IF(L11>=K11,"مكتمل",IF(L11=0,"لا يوجد","عجز"))) | P11: =IF(CAP<=$D$4,D11*CAP/$D$4,IF(CAP>=$J$4,J11*CAP/$J$4,INDEX($D11:$J11,$D$3)+$E$3*(INDEX($D11:$J11,$D$3+1)-INDEX($D11:$J11,$D$3))))
A12: 8 | B12: طبيب | C12: استشاري جهاز هضمي وكبد | D12: 0 | E12: 1 | F12: 1 | G12: 1 | H12: 2 | I12: 3 | J12: 4 | K12: =IF(RMODE="تقريب لأعلى",ROUNDUP(P12,0),ROUND(P12,0)) | M12: =L12-K12 | N12: =IF(K12=0,"",L12/K12) | O12: =IF(K12=0,"لا ينطبق",IF(L12>=K12,"مكتمل",IF(L12=0,"لا يوجد","عجز"))) | P12: =IF(CAP<=$D$4,D12*CAP/$D$4,IF(CAP>=$J$4,J12*CAP/$J$4,INDEX($D12:$J12,$D$3)+$E$3*(INDEX($D12:$J12,$D$3+1)-INDEX($D12:$J12,$D$3))))
A13: 9 | B13: طبيب | C13: أخصائي جهاز هضمي وكبد | D13: 0 | E13: 1 | F13: 1 | G13: 2 | H13: 3 | I13: 3 | J13: 3 | K13: =IF(RMODE="تقريب لأعلى",ROUNDUP(P13,0),ROUND(P13,0)) | M13: =L13-K13 | N13: =IF(K13=0,"",L13/K13) | O13: =IF(K13=0,"لا ينطبق",IF(L13>=K13,"مكتمل",IF(L13=0,"لا يوجد","عجز"))) | P13: =IF(CAP<=$D$4,D13*CAP/$D$4,IF(CAP>=$J$4,J13*CAP/$J$4,INDEX($D13:$J13,$D$3)+$E$3*(INDEX($D13:$J13,$D$3+1)-INDEX($D13:$J13,$D$3))))
A14: 10 | B14: طبيب | C14: مقيم جهاز هضمي وكبد | D14: 0 | E14: 1 | F14: 1 | G14: 1 | H14: 2 | I14: 2 | J14: 3 | K14: =IF(RMODE="تقريب لأعلى",ROUNDUP(P14,0),ROUND(P14,0)) | M14: =L14-K14 | N14: =IF(K14=0,"",L14/K14) | O14: =IF(K14=0,"لا ينطبق",IF(L14>=K14,"مكتمل",IF(L14=0,"لا يوجد","عجز"))) | P14: =IF(CAP<=$D$4,D14*CAP/$D$4,IF(CAP>=$J$4,J14*CAP/$J$4,INDEX($D14:$J14,$D$3)+$E$3*(INDEX($D14:$J14,$D$3+1)-INDEX($D14:$J14,$D$3))))
A15: 11 | B15: طبيب | C15: استشاري أعصاب | D15: 0 | E15: 0 | F15: 1 | G15: 2 | H15: 3 | I15: 4 | J15: 6 | K15: =IF(RMODE="تقريب لأعلى",ROUNDUP(P15,0),ROUND(P15,0)) | M15: =L15-K15 | N15: =IF(K15=0,"",L15/K15) | O15: =IF(K15=0,"لا ينطبق",IF(L15>=K15,"مكتمل",IF(L15=0,"لا يوجد","عجز"))) | P15: =IF(CAP<=$D$4,D15*CAP/$D$4,IF(CAP>=$J$4,J15*CAP/$J$4,INDEX($D15:$J15,$D$3)+$E$3*(INDEX($D15:$J15,$D$3+1)-INDEX($D15:$J15,$D$3))))
A16: 12 | B16: طبيب | C16: أخصائي أعصاب | D16: 0 | E16: 0 | F16: 2 | G16: 2 | H16: 3 | I16: 4 | J16: 5 | K16: =IF(RMODE="تقريب لأعلى",ROUNDUP(P16,0),ROUND(P16,0)) | M16: =L16-K16 | N16: =IF(K16=0,"",L16/K16) | O16: =IF(K16=0,"لا ينطبق",IF(L16>=K16,"مكتمل",IF(L16=0,"لا يوجد","عجز"))) | P16: =IF(CAP<=$D$4,D16*CAP/$D$4,IF(CAP>=$J$4,J16*CAP/$J$4,INDEX($D16:$J16,$D$3)+$E$3*(INDEX($D16:$J16,$D$3+1)-INDEX($D16:$J16,$D$3))))
... A24: 20 | B24: طبيب | C24: أخصائي غدد صماء وسكري | D24: 1 | E24: 2 | F24: 2 | G24: 2 | H24: 3 | I24: 3 | J24: 3 | K24: =IF(RMODE="تقريب لأعلى",ROUNDUP(P24,0),ROUND(P24,0)) | M24: =L24-K24 | N24: =IF(K24=0,"",L24/K24) | O24: =IF(K24=0,"لا ينطبق",IF(L24>=K24,"مكتمل",IF(L24=0,"لا يوجد","عجز"))) | P24: =IF(CAP<=$D$4,D24*CAP/$D$4,IF(CAP>=$J$4,J24*CAP/$J$4,INDEX($D24:$J24,$D$3)+$E$3*(INDEX($D24:$J24,$D$3+1)-INDEX($D24:$J24,$D$3))))
A25: 21 | B25: طبيب | C25: استشاري أمراض دم وأورام | D25: 0 | E25: 0 | F25: 1 | G25: 1 | H25: 2 | I25: 3 | J25: 4 | K25: =IF(RMODE="تقريب لأعلى",ROUNDUP(P25,0),ROUND(P25,0)) | M25: =L25-K25 | N25: =IF(K25=0,"",L25/K25) | O25: =IF(K25=0,"لا ينطبق",IF(L25>=K25,"مكتمل",IF(L25=0,"لا يوجد","عجز"))) | P25: =IF(CAP<=$D$4,D25*CAP/$D$4,IF(CAP>=$J$4,J25*CAP/$J$4,INDEX($D25:$J25,$D$3)+$E$3*(INDEX($D25:$J25,$D$3+1)-INDEX($D25:$J25,$D$3)))) | Q25: إيضاح 37: تطبق المسميات 21-30 عند توفر خدمات الأورام
A26: 22 | B26: طبيب | C26: أخصائي أمراض دم وأورام | D26: 0 | E26: 0 | F26: 1 | G26: 2 | H26: 4 | I26: 5 | J26: 6 | K26: =IF(RMODE="تقريب لأعلى",ROUNDUP(P26,0),ROUND(P26,0)) | M26: =L26-K26 | N26: =IF(K26=0,"",L26/K26) | O26: =IF(K26=0,"لا ينطبق",IF(L26>=K26,"مكتمل",IF(L26=0,"لا يوجد","عجز"))) | P26: =IF(CAP<=$D$4,D26*CAP/$D$4,IF(CAP>=$J$4,J26*CAP/$J$4,INDEX($D26:$J26,$D$3)+$E$3*(INDEX($D26:$J26,$D$3+1)-INDEX($D26:$J26,$D$3)))) | Q26: إيضاح 37
A27: 23 | B27: طبيب | C27: استشاري أورام كبار | D27: 0 | E27: 0 | F27: 0 | G27: 1 | H27: 1 | I27: 2 | J27: 2 | K27: =IF(RMODE="تقريب لأعلى",ROUNDUP(P27,0),ROUND(P27,0)) | M27: =L27-K27 | N27: =IF(K27=0,"",L27/K27) | O27: =IF(K27=0,"لا ينطبق",IF(L27>=K27,"مكتمل",IF(L27=0,"لا يوجد","عجز"))) | P27: =IF(CAP<=$D$4,D27*CAP/$D$4,IF(CAP>=$J$4,J27*CAP/$J$4,INDEX($D27:$J27,$D$3)+$E$3*(INDEX($D27:$J27,$D$3+1)-INDEX($D27:$J27,$D$3)))) | Q27: إيضاح 37
A28: 24 | B28: طبيب | C28: أخصائي أورام كبار | D28: 0 | E28: 1 | F28: 1 | G28: 2 | H28: 2 | I28: 2 | J28: 3 | K28: =IF(RMODE="تقريب لأعلى",ROUNDUP(P28,0),ROUND(P28,0)) | M28: =L28-K28 | N28: =IF(K28=0,"",L28/K28) | O28: =IF(K28=0,"لا ينطبق",IF(L28>=K28,"مكتمل",IF(L28=0,"لا يوجد","عجز"))) | P28: =IF(CAP<=$D$4,D28*CAP/$D$4,IF(CAP>=$J$4,J28*CAP/$J$4,INDEX($D28:$J28,$D$3)+$E$3*(INDEX($D28:$J28,$D$3+1)-INDEX($D28:$J28,$D$3)))) | Q28: إيضاح 37
A29: 25 | B29: طبيب | C29: استشاري علاج إشعاعي أورام | D29: 0 | E29: 0 | F29: 0 | G29: 0 | H29: 2 | I29: 2 | J29: 3 | K29: =IF(RMODE="تقريب لأعلى",ROUNDUP(P29,0),ROUND(P29,0)) | M29: =L29-K29 | N29: =IF(K29=0,"",L29/K29) | O29: =IF(K29=0,"لا ينطبق",IF(L29>=K29,"مكتمل",IF(L29=0,"لا يوجد","عجز"))) | P29: =IF(CAP<=$D$4,D29*CAP/$D$4,IF(CAP>=$J$4,J29*CAP/$J$4,INDEX($D29:$J29,$D$3)+$E$3*(INDEX($D29:$J29,$D$3+1)-INDEX($D29:$J29,$D$3)))) | Q29: إيضاح 37
A30: 26 | B30: طبيب | C30: أخصائي علاج إشعاعي أورام | D30: 0 | E30: 0 | F30: 1 | G30: 2 | H30: 2 | I30: 3 | J30: 3 | K30: =IF(RMODE="تقريب لأعلى",ROUNDUP(P30,0),ROUND(P30,0)) | M30: =L30-K30 | N30: =IF(K30=0,"",L30/K30) | O30: =IF(K30=0,"لا ينطبق",IF(L30>=K30,"مكتمل",IF(L30=0,"لا يوجد","عجز"))) | P30: =IF(CAP<=$D$4,D30*CAP/$D$4,IF(CAP>=$J$4,J30*CAP/$J$4,INDEX($D30:$J30,$D$3)+$E$3*(INDEX($D30:$J30,$D$3+1)-INDEX($D30:$J30,$D$3)))) | Q30: إيضاح 37
A31: 27 | B31: طبيب | C31: استشاري علاج تلطيفي أورام | D31: 0 | E31: 0 | F31: 0 | G31: 1 | H31: 1 | I31: 2 | J31: 2 | K31: =IF(RMODE="تقريب لأعلى",ROUNDUP(P31,0),ROUND(P31,0)) | M31: =L31-K31 | N31: =IF(K31=0,"",L31/K31) | O31: =IF(K31=0,"لا ينطبق",IF(L31>=K31,"مكتمل",IF(L31=0,"لا يوجد","عجز"))) | P31: =IF(CAP<=$D$4,D31*CAP/$D$4,IF(CAP>=$J$4,J31*CAP/$J$4,INDEX($D31:$J31,$D$3)+$E$3*(INDEX($D31:$J31,$D$3+1)-INDEX($D31:$J31,$D$3)))) | Q31: إيضاح 37
A32: 28 | B32: طبيب | C32: أخصائي علاج تلطيفي أورام | D32: 0 | E32: 0 | F32: 1 | G32: 1 | H32: 2 | I32: 2 | J32: 2 | K32: =IF(RMODE="تقريب لأعلى",ROUNDUP(P32,0),ROUND(P32,0)) | M32: =L32-K32 | N32: =IF(K32=0,"",L32/K32) | O32: =IF(K32=0,"لا ينطبق",IF(L32>=K32,"مكتمل",IF(L32=0,"لا يوجد","عجز"))) | P32: =IF(CAP<=$D$4,D32*CAP/$D$4,IF(CAP>=$J$4,J32*CAP/$J$4,INDEX($D32:$J32,$D$3)+$E$3*(INDEX($D32:$J32,$D$3+1)-INDEX($D32:$J32,$D$3)))) | Q32: إيضاح 37
A33: 29 | B33: طبيب | C33: استشاري أورام أطفال | D33: 0 | E33: 0 | F33: 0 | G33: 1 | H33: 1 | I33: 2 | J33: 2 | K33: =IF(RMODE="تقريب لأعلى",ROUNDUP(P33,0),ROUND(P33,0)) | M33: =L33-K33 | N33: =IF(K33=0,"",L33/K33) | O33: =IF(K33=0,"لا ينطبق",IF(L33>=K33,"مكتمل",IF(L33=0,"لا يوجد","عجز"))) | P33: =IF(CAP<=$D$4,D33*CAP/$D$4,IF(CAP>=$J$4,J33*CAP/$J$4,INDEX($D33:$J33,$D$3)+$E$3*(INDEX($D33:$J33,$D$3+1)-INDEX($D33:$J33,$D$3)))) | Q33: إيضاح 37
A34: 30 | B34: طبيب | C34: أخصائي أورام أطفال | D34: 0 | E34: 0 | F34: 1 | G34: 2 | H34: 2 | I34: 3 | J34: 3 | K34: =IF(RMODE="تقريب لأعلى",ROUNDUP(P34,0),ROUND(P34,0)) | M34: =L34-K34 | N34: =IF(K34=0,"",L34/K34) | O34: =IF(K34=0,"لا ينطبق",IF(L34>=K34,"مكتمل",IF(L34=0,"لا يوجد","عجز"))) | P34: =IF(CAP<=$D$4,D34*CAP/$D$4,IF(CAP>=$J$4,J34*CAP/$J$4,INDEX($D34:$J34,$D$3)+$E$3*(INDEX($D34:$J34,$D$3+1)-INDEX($D34:$J34,$D$3)))) | Q34: إيضاح 37
A35: 31 | B35: طبيب | C35: استشاري أمراض وراثية واستقلابية | D35: 0 | E35: 0 | F35: 0 | G35: 0 | H35: 1 | I35: 2 | J35: 2 | K35: =IF(RMODE="تقريب لأعلى",ROUNDUP(P35,0),ROUND(P35,0)) | M35: =L35-K35 | N35: =IF(K35=0,"",L35/K35) | O35: =IF(K35=0,"لا ينطبق",IF(L35>=K35,"مكتمل",IF(L35=0,"لا يوجد","عجز"))) | P35: =IF(CAP<=$D$4,D35*CAP/$D$4,IF(CAP>=$J$4,J35*CAP/$J$4,INDEX($D35:$J35,$D$3)+$E$3*(INDEX($D35:$J35,$D$3+1)-INDEX($D35:$J35,$D$3))))
A36: 32 | B36: طبيب | C36: أخصائي أمراض وراثية واستقلابية | D36: 0 | E36: 0 | F36: 0 | G36: 2 | H36: 2 | I36: 3 | J36: 3 | K36: =IF(RMODE="تقريب لأعلى",ROUNDUP(P36,0),ROUND(P36,0)) | M36: =L36-K36 | N36: =IF(K36=0,"",L36/K36) | O36: =IF(K36=0,"لا ينطبق",IF(L36>=K36,"مكتمل",IF(L36=0,"لا يوجد","عجز"))) | P36: =IF(CAP<=$D$4,D36*CAP/$D$4,IF(CAP>=$J$4,J36*CAP/$J$4,INDEX($D36:$J36,$D$3)+$E$3*(INDEX($D36:$J36,$D$3+1)-INDEX($D36:$J36,$D$3))))
A37: 33 | B37: طبيب | C37: استشاري أمراض صدرية | D37: 0 | E37: 1 | F37: 1 | G37: 2 | H37: 2 | I37: 3 | J37: 3 | K37: =IF(RMODE="تقريب لأعلى",ROUNDUP(P37,0),ROUND(P37,0)) | M37: =L37-K37 | N37: =IF(K37=0,"",L37/K37) | O37: =IF(K37=0,"لا ينطبق",IF(L37>=K37,"مكتمل",IF(L37=0,"لا يوجد","عجز"))) | P37: =IF(CAP<=$D$4,D37*CAP/$D$4,IF(CAP>=$J$4,J37*CAP/$J$4,INDEX($D37:$J37,$D$3)+$E$3*(INDEX($D37:$J37,$D$3+1)-INDEX($D37:$J37,$D$3))))
A38: 34 | B38: طبيب | C38: أخصائي أمراض صدرية | D38: 1 | E38: 1 | F38: 2 | G38: 2 | H38: 3 | I38: 4 | J38: 5 | K38: =IF(RMODE="تقريب لأعلى",ROUNDUP(P38,0),ROUND(P38,0)) | M38: =L38-K38 | N38: =IF(K38=0,"",L38/K38) | O38: =IF(K38=0,"لا ينطبق",IF(L38>=K38,"مكتمل",IF(L38=0,"لا يوجد","عجز"))) | P38: =IF(CAP<=$D$4,D38*CAP/$D$4,IF(CAP>=$J$4,J38*CAP/$J$4,INDEX($D38:$J38,$D$3)+$E$3*(INDEX($D38:$J38,$D$3+1)-INDEX($D38:$J38,$D$3))))
A39: 35 | B39: طبيب | C39: استشاري أمراض معدية | D39: 0 | E39: 0 | F39: 1 | G39: 1 | H39: 3 | I39: 4 | J39: 4 | K39: =IF(RMODE="تقريب لأعلى",ROUNDUP(P39,0),ROUND(P39,0)) | M39: =L39-K39 | N39: =IF(K39=0,"",L39/K39) | O39: =IF(K39=0,"لا ينطبق",IF(L39>=K39,"مكتمل",IF(L39=0,"لا يوجد","عجز"))) | P39: =IF(CAP<=$D$4,D39*CAP/$D$4,IF(CAP>=$J$4,J39*CAP/$J$4,INDEX($D39:$J39,$D$3)+$E$3*(INDEX($D39:$J39,$D$3+1)-INDEX($D39:$J39,$D$3))))
A40: 36 | B40: طبيب | C40: أخصائي أمراض معدية | D40: 0 | E40: 1 | F40: 1 | G40: 1 | H40: 3 | I40: 3 | J40: 4 | K40: =IF(RMODE="تقريب لأعلى",ROUNDUP(P40,0),ROUND(P40,0)) | M40: =L40-K40 | N40: =IF(K40=0,"",L40/K40) | O40: =IF(K40=0,"لا ينطبق",IF(L40>=K40,"مكتمل",IF(L40=0,"لا يوجد","عجز"))) | P40: =IF(CAP<=$D$4,D40*CAP/$D$4,IF(CAP>=$J$4,J40*CAP/$J$4,INDEX($D40:$J40,$D$3)+$E$3*(INDEX($D40:$J40,$D$3+1)-INDEX($D40:$J40,$D$3))))
A41: 37 | B41: طبيب | C41: استشاري روماتيزم | D41: 0 | E41: 0 | F41: 0 | G41: 1 | H41: 2 | I41: 3 | J41: 3 | K41: =IF(RMODE="تقريب لأعلى",ROUNDUP(P41,0),ROUND(P41,0)) | M41: =L41-K41 | N41: =IF(K41=0,"",L41/K41) | O41: =IF(K41=0,"لا ينطبق",IF(L41>=K41,"مكتمل",IF(L41=0,"لا يوجد","عجز"))) | P41: =IF(CAP<=$D$4,D41*CAP/$D$4,IF(CAP>=$J$4,J41*CAP/$J$4,INDEX($D41:$J41,$D$3)+$E$3*(INDEX($D41:$J41,$D$3+1)-INDEX($D41:$J41,$D$3))))
A42: 38 | B42: طبيب | C42: أخصائي روماتيزم | D42: 0 | E42: 0 | F42: 0 | G42: 1 | H42: 2 | I42: 2 | J42: 3 | K42: =IF(RMODE="تقريب لأعلى",ROUNDUP(P42,0),ROUND(P42,0)) | M42: =L42-K42 | N42: =IF(K42=0,"",L42/K42) | O42: =IF(K42=0,"لا ينطبق",IF(L42>=K42,"مكتمل",IF(L42=0,"لا يوجد","عجز"))) | P42: =IF(CAP<=$D$4,D42*CAP/$D$4,IF(CAP>=$J$4,J42*CAP/$J$4,INDEX($D42:$J42,$D$3)+$E$3*(INDEX($D42:$J42,$D$3+1)-INDEX($D42:$J42,$D$3))))
A43: 39 | B43: طبيب | C43: طبيب استشاري طب نفسي | D43: 1 | E43: 1 | F43: 1 | G43: 1 | H43: 1 | I43: 1 | J43: 2 | K43: =IF(RMODE="تقريب لأعلى",ROUNDUP(P43,0),ROUND(P43,0)) | M43: =L43-K43 | N43: =IF(K43=0,"",L43/K43) | O43: =IF(K43=0,"لا ينطبق",IF(L43>=K43,"مكتمل",IF(L43=0,"لا يوجد","عجز"))) | P43: =IF(CAP<=$D$4,D43*CAP/$D$4,IF(CAP>=$J$4,J43*CAP/$J$4,INDEX($D43:$J43,$D$3)+$E$3*(INDEX($D43:$J43,$D$3+1)-INDEX($D43:$J43,$D$3))))
A44: 40 | B44: طبيب | C44: طبيب أخصائي طب نفسي | D44: 0 | E44: 1 | F44: 1 | G44: 1 | H44: 1 | I44: 1 | J44: 1 | K44: =IF(RMODE="تقريب لأعلى",ROUNDUP(P44,0),ROUND(P44,0)) | M44: =L44-K44 | N44: =IF(K44=0,"",L44/K44) | O44: =IF(K44=0,"لا ينطبق",IF(L44>=K44,"مكتمل",IF(L44=0,"لا يوجد","عجز"))) | P44: =IF(CAP<=$D$4,D44*CAP/$D$4,IF(CAP>=$J$4,J44*CAP/$J$4,INDEX($D44:$J44,$D$3)+$E$3*(INDEX($D44:$J44,$D$3+1)-INDEX($D44:$J44,$D$3))))
A45: 41 | B45: طبيب | C45: طبيب مقيم نفسي | D45: 1 | E45: 2 | F45: 3 | G45: 3 | H45: 5 | I45: 6 | J45: 6 | K45: =IF(RMODE="تقريب لأعلى",ROUNDUP(P45,0),ROUND(P45,0)) | M45: =L45-K45 | N45: =IF(K45=0,"",L45/K45) | O45: =IF(K45=0,"لا ينطبق",IF(L45>=K45,"مكتمل",IF(L45=0,"لا يوجد","عجز"))) | P45: =IF(CAP<=$D$4,D45*CAP/$D$4,IF(CAP>=$J$4,J45*CAP/$J$4,INDEX($D45:$J45,$D$3)+$E$3*(INDEX($D45:$J45,$D$3+1)-INDEX($D45:$J45,$D$3))))
A46: 42 | B46: طبيب | C46: استشاري طب نفسي أطفال ومراهقين | D46: 0 | E46: 1 | F46: 1 | G46: 2 | H46: 2 | I46: 3 | J46: 3 | K46: =IF(RMODE="تقريب لأعلى",ROUNDUP(P46,0),ROUND(P46,0)) | M46: =L46-K46 | N46: =IF(K46=0,"",L46/K46) | O46: =IF(K46=0,"لا ينطبق",IF(L46>=K46,"مكتمل",IF(L46=0,"لا يوجد","عجز"))) | P46: =IF(CAP<=$D$4,D46*CAP/$D$4,IF(CAP>=$J$4,J46*CAP/$J$4,INDEX($D46:$J46,$D$3)+$E$3*(INDEX($D46:$J46,$D$3+1)-INDEX($D46:$J46,$D$3))))
... A49: 45 | B49: طبيب | C49: أخصائي أمراض جلدية وتناسلية | D49: 1 | E49: 1 | F49: 1 | G49: 2 | H49: 3 | I49: 4 | J49: 5 | K49: =IF(RMODE="تقريب لأعلى",ROUNDUP(P49,0),ROUND(P49,0)) | M49: =L49-K49 | N49: =IF(K49=0,"",L49/K49) | O49: =IF(K49=0,"لا ينطبق",IF(L49>=K49,"مكتمل",IF(L49=0,"لا يوجد","عجز"))) | P49: =IF(CAP<=$D$4,D49*CAP/$D$4,IF(CAP>=$J$4,J49*CAP/$J$4,INDEX($D49:$J49,$D$3)+$E$3*(INDEX($D49:$J49,$D$3+1)-INDEX($D49:$J49,$D$3))))
...

Sheet عام - أخصائي غير طبيب
A1: عام - أخصائي غير طبيب
A2: الملحق (1) — أخصائي غير طبيب، ويشمل التمريض والقبالة (صفحات 26-27)
C3: معاملا الاستيفاء ◄ | D3: =IFERROR(MATCH(CAP,$D$4:$J$4,1),1) | E3: =IF(OR(CAP<=$D$4,CAP>=$J$4),0,(CAP-INDEX($D$4:$J$4,$D$3))/(INDEX($D$4:$J$4,$D$3+1)-INDEX($D$4:$J$4,$D$3)))
A4: م | B4: الفئة | C4: المسمى الوظيفي | D4: 50 | E4: 100 | F4: 150 | G4: 200 | H4: 300 | I4: 400 | J4: 500 | K4: الاحتياج للسعة المدخلة | L4: الموجود فعلياً | M4: الفجوة (+فائض / -عجز) | N4: نسبة التغطية | O4: الحالة | P4: القيمة قبل التقريب | Q4: ملاحظات
A5: 1 | B5: أخصائي غير طبيب | C5: أخصائي أشعة | D5: 9 | E5: 22 | F5: 42 | G5: 42 | H5: 70 | I5: 108 | J5: 108 | K5: =IF(RMODE="تقريب لأعلى",ROUNDUP(P5,0),ROUND(P5,0)) | M5: =L5-K5 | N5: =IF(K5=0,"",L5/K5) | O5: =IF(K5=0,"لا ينطبق",IF(L5>=K5,"مكتمل",IF(L5=0,"لا يوجد","عجز"))) | P5: =IF(CAP<=$D$4,D5*CAP/$D$4,IF(CAP>=$J$4,J5*CAP/$J$4,INDEX($D5:$J5,$D$3)+$E$3*(INDEX($D5:$J5,$D$3+1)-INDEX($D5:$J5,$D$3))))
A6: 2 | B6: أخصائي غير طبيب | C6: أخصائي أول أشعة | D6: 1 | E6: 4 | F6: 5 | G6: 5 | H6: 7 | I6: 12 | J6: 14 | K6: =IF(RMODE="تقريب لأعلى",ROUNDUP(P6,0),ROUND(P6,0)) | M6: =L6-K6 | N6: =IF(K6=0,"",L6/K6) | O6: =IF(K6=0,"لا ينطبق",IF(L6>=K6,"مكتمل",IF(L6=0,"لا يوجد","عجز"))) | P6: =IF(CAP<=$D$4,D6*CAP/$D$4,IF(CAP>=$J$4,J6*CAP/$J$4,INDEX($D6:$J6,$D$3)+$E$3*(INDEX($D6:$J6,$D$3+1)-INDEX($D6:$J6,$D$3))))
A7: 3 | B7: أخصائي غير طبيب | C7: أخصائي استشاري أشعة | D7: 0 | E7: 0 | F7: 1 | G7: 2 | H7: 3 | I7: 8 | J7: 10 | K7: =IF(RMODE="تقريب لأعلى",ROUNDUP(P7,0),ROUND(P7,0)) | M7: =L7-K7 | N7: =IF(K7=0,"",L7/K7) | O7: =IF(K7=0,"لا ينطبق",IF(L7>=K7,"مكتمل",IF(L7=0,"لا يوجد","عجز"))) | P7: =IF(CAP<=$D$4,D7*CAP/$D$4,IF(CAP>=$J$4,J7*CAP/$J$4,INDEX($D7:$J7,$D$3)+$E$3*(INDEX($D7:$J7,$D$3+1)-INDEX($D7:$J7,$D$3))))
A8: 4 | B8: أخصائي غير طبيب | C8: أخصائي طب نووي (غير طبيب) | D8: 0 | E8: 0 | F8: 0 | G8: 0 | H8: 4 | I8: 7 | J8: 7 | K8: =IF(RMODE="تقريب لأعلى",ROUNDUP(P8,0),ROUND(P8,0)) | M8: =L8-K8 | N8: =IF(K8=0,"",L8/K8) | O8: =IF(K8=0,"لا ينطبق",IF(L8>=K8,"مكتمل",IF(L8=0,"لا يوجد","عجز"))) | P8: =IF(CAP<=$D$4,D8*CAP/$D$4,IF(CAP>=$J$4,J8*CAP/$J$4,INDEX($D8:$J8,$D$3)+$E$3*(INDEX($D8:$J8,$D$3+1)-INDEX($D8:$J8,$D$3))))
A9: 5 | B9: أخصائي غير طبيب | C9: أخصائي استشاري فيزياء طبية | D9: 0 | E9: 0 | F9: 0 | G9: 1 | H9: 1 | I9: 2 | J9: 2 | K9: =IF(RMODE="تقريب لأعلى",ROUNDUP(P9,0),ROUND(P9,0)) | M9: =L9-K9 | N9: =IF(K9=0,"",L9/K9) | O9: =IF(K9=0,"لا ينطبق",IF(L9>=K9,"مكتمل",IF(L9=0,"لا يوجد","عجز"))) | P9: =IF(CAP<=$D$4,D9*CAP/$D$4,IF(CAP>=$J$4,J9*CAP/$J$4,INDEX($D9:$J9,$D$3)+$E$3*(INDEX($D9:$J9,$D$3+1)-INDEX($D9:$J9,$D$3))))
A10: 6 | B10: أخصائي غير طبيب | C10: أخصائي أول فيزياء طبية | D10: 0 | E10: 0 | F10: 1 | G10: 1 | H10: 1 | I10: 2 | J10: 2 | K10: =IF(RMODE="تقريب لأعلى",ROUNDUP(P10,0),ROUND(P10,0)) | M10: =L10-K10 | N10: =IF(K10=0,"",L10/K10) | O10: =IF(K10=0,"لا ينطبق",IF(L10>=K10,"مكتمل",IF(L10=0,"لا يوجد","عجز"))) | P10: =IF(CAP<=$D$4,D10*CAP/$D$4,IF(CAP>=$J$4,J10*CAP/$J$4,INDEX($D10:$J10,$D$3)+$E$3*(INDEX($D10:$J10,$D$3+1)-INDEX($D10:$J10,$D$3))))
A11: 7 | B11: أخصائي غير طبيب | C11: أخصائي فيزياء طبية | D11: 1 | E11: 2 | F11: 2 | G11: 3 | H11: 3 | I11: 3 | J11: 3 | K11: =IF(RMODE="تقريب لأعلى",ROUNDUP(P11,0),ROUND(P11,0)) | M11: =L11-K11 | N11: =IF(K11=0,"",L11/K11) | O11: =IF(K11=0,"لا ينطبق",IF(L11>=K11,"مكتمل",IF(L11=0,"لا يوجد","عجز"))) | P11: =IF(CAP<=$D$4,D11*CAP/$D$4,IF(CAP>=$J$4,J11*CAP/$J$4,INDEX($D11:$J11,$D$3)+$E$3*(INDEX($D11:$J11,$D$3+1)-INDEX($D11:$J11,$D$3))))
A12: 8 | B12: أخصائي غير طبيب | C12: أخصائي مختبر وبنك دم | D12: 6 | E12: 11 | F12: 18 | G12: 20 | H12: 22 | I12: 32 | J12: 45 | K12: =IF(RMODE="تقريب لأعلى",ROUNDUP(P12,0),ROUND(P12,0)) | M12: =L12-K12 | N12: =IF(K12=0,"",L12/K12) | O12: =IF(K12=0,"لا ينطبق",IF(L12>=K12,"مكتمل",IF(L12=0,"لا يوجد","عجز"))) | P12: =IF(CAP<=$D$4,D12*CAP/$D$4,IF(CAP>=$J$4,J12*CAP/$J$4,INDEX($D12:$J12,$D$3)+$E$3*(INDEX($D12:$J12,$D$3+1)-INDEX($D12:$J12,$D$3))))
A13: 9 | B13: أخصائي غير طبيب | C13: أخصائي أول مختبر وبنك دم | D13: 4 | E13: 5 | F13: 6 | G13: 8 | H13: 10 | I13: 10 | J13: 15 | K13: =IF(RMODE="تقريب لأعلى",ROUNDUP(P13,0),ROUND(P13,0)) | M13: =L13-K13 | N13: =IF(K13=0,"",L13/K13) | O13: =IF(K13=0,"لا ينطبق",IF(L13>=K13,"مكتمل",IF(L13=0,"لا يوجد","عجز"))) | P13: =IF(CAP<=$D$4,D13*CAP/$D$4,IF(CAP>=$J$4,J13*CAP/$J$4,INDEX($D13:$J13,$D$3)+$E$3*(INDEX($D13:$J13,$D$3+1)-INDEX($D13:$J13,$D$3))))
A14: 10 | B14: أخصائي غير طبيب | C14: أخصائي استشاري مختبر وبنك دم | D14: 0 | E14: 1 | F14: 1 | G14: 2 | H14: 3 | I14: 5 | J14: 10 | K14: =IF(RMODE="تقريب لأعلى",ROUNDUP(P14,0),ROUND(P14,0)) | M14: =L14-K14 | N14: =IF(K14=0,"",L14/K14) | O14: =IF(K14=0,"لا ينطبق",IF(L14>=K14,"مكتمل",IF(L14=0,"لا يوجد","عجز"))) | P14: =IF(CAP<=$D$4,D14*CAP/$D$4,IF(CAP>=$J$4,J14*CAP/$J$4,INDEX($D14:$J14,$D$3)+$E$3*(INDEX($D14:$J14,$D$3+1)-INDEX($D14:$J14,$D$3))))
A15: 11 | B15: أخصائي غير طبيب | C15: أخصائي مختبر أجنة | D15: 0 | E15: 0 | F15: 0 | G15: 1 | H15: 1 | I15: 2 | J15: 3 | K15: =IF(RMODE="تقريب لأعلى",ROUNDUP(P15,0),ROUND(P15,0)) | M15: =L15-K15 | N15: =IF(K15=0,"",L15/K15) | O15: =IF(K15=0,"لا ينطبق",IF(L15>=K15,"مكتمل",IF(L15=0,"لا يوجد","عجز"))) | P15: =IF(CAP<=$D$4,D15*CAP/$D$4,IF(CAP>=$J$4,J15*CAP/$J$4,INDEX($D15:$J15,$D$3)+$E$3*(INDEX($D15:$J15,$D$3+1)-INDEX($D15:$J15,$D$3)))) | Q15: إيضاح 39: مرتبط باعتماد مركز للعقم
A16: 12 | B16: أخصائي غير طبيب | C16: أخصائي علاج طبيعي | D16: 4 | E16: 6 | F16: 9 | G16: 12 | H16: 18 | I16: 24 | J16: 30 | K16: =IF(RMODE="تقريب لأعلى",ROUNDUP(P16,0),ROUND(P16,0)) | M16: =L16-K16 | N16: =IF(K16=0,"",L16/K16) | O16: =IF(K16=0,"لا ينطبق",IF(L16>=K16,"مكتمل",IF(L16=0,"لا يوجد","عجز"))) | P16: =IF(CAP<=$D$4,D16*CAP/$D$4,IF(CAP>=$J$4,J16*CAP/$J$4,INDEX($D16:$J16,$D$3)+$E$3*(INDEX($D16:$J16,$D$3+1)-INDEX($D16:$J16,$D$3))))
A17: 13 | B17: أخصائي غير طبيب | C17: أخصائي أول علاج طبيعي | D17: 1 | E17: 2 | F17: 3 | G17: 4 | H17: 5 | I17: 8 | J17: 10 | K17: =IF(RMODE="تقريب لأعلى",ROUNDUP(P17,0),ROUND(P17,0)) | M17: =L17-K17 | N17: =IF(K17=0,"",L17/K17) | O17: =IF(K17=0,"لا ينطبق",IF(L17>=K17,"مكتمل",IF(L17=0,"لا يوجد","عجز"))) | P17: =IF(CAP<=$D$4,D17*CAP/$D$4,IF(CAP>=$J$4,J17*CAP/$J$4,INDEX($D17:$J17,$D$3)+$E$3*(INDEX($D17:$J17,$D$3+1)-INDEX($D17:$J17,$D$3))))
A18: 14 | B18: أخصائي غير طبيب | C18: أخصائي استشاري علاج طبيعي | D18: 0 | E18: 1 | F18: 1 | G18: 2 | H18: 3 | I18: 4 | J18: 5 | K18: =IF(RMODE="تقريب لأعلى",ROUNDUP(P18,0),ROUND(P18,0)) | M18: =L18-K18 | N18: =IF(K18=0,"",L18/K18) | O18: =IF(K18=0,"لا ينطبق",IF(L18>=K18,"مكتمل",IF(L18=0,"لا يوجد","عجز"))) | P18: =IF(CAP<=$D$4,D18*CAP/$D$4,IF(CAP>=$J$4,J18*CAP/$J$4,INDEX($D18:$J18,$D$3)+$E$3*(INDEX($D18:$J18,$D$3+1)-INDEX($D18:$J18,$D$3))))
A19: 15 | B19: أخصائي غير طبيب | C19: أخصائي علاج وظيفي | D19: 0 | E19: 2 | F19: 3 | G19: 4 | H19: 4 | I19: 6 | J19: 6 | K19: =IF(RMODE="تقريب لأعلى",ROUNDUP(P19,0),ROUND(P19,0)) | M19: =L19-K19 | N19: =IF(K19=0,"",L19/K19) | O19: =IF(K19=0,"لا ينطبق",IF(L19>=K19,"مكتمل",IF(L19=0,"لا يوجد","عجز"))) | P19: =IF(CAP<=$D$4,D19*CAP/$D$4,IF(CAP>=$J$4,J19*CAP/$J$4,INDEX($D19:$J19,$D$3)+$E$3*(INDEX($D19:$J19,$D$3+1)-INDEX($D19:$J19,$D$3))))
A20: 16 | B20: أخصائي غير طبيب | C20: أخصائي أول علاج وظيفي | D20: 0 | E20: 0 | F20: 0 | G20: 1 | H20: 2 | I20: 3 | J20: 4 | K20: =IF(RMODE="تقريب لأعلى",ROUNDUP(P20,0),ROUND(P20,0)) | M20: =L20-K20 | N20: =IF(K20=0,"",L20/K20) | O20: =IF(K20=0,"لا ينطبق",IF(L20>=K20,"مكتمل",IF(L20=0,"لا يوجد","عجز"))) | P20: =IF(CAP<=$D$4,D20*CAP/$D$4,IF(CAP>=$J$4,J20*CAP/$J$4,INDEX($D20:$J20,$D$3)+$E$3*(INDEX($D20:$J20,$D$3+1)-INDEX($D20:$J20,$D$3))))
A21: 17 | B21: أخصائي غير طبيب | C21: أخصائي استشاري علاج وظيفي | D21: 0 | E21: 0 | F21: 0 | G21: 0 | H21: 0 | I21: 1 | J21: 2 | K21: =IF(RMODE="تقريب لأعلى",ROUNDUP(P21,0),ROUND(P21,0)) | M21: =L21-K21 | N21: =IF(K21=0,"",L21/K21) | O21: =IF(K21=0,"لا ينطبق",IF(L21>=K21,"مكتمل",IF(L21=0,"لا يوجد","عجز"))) | P21: =IF(CAP<=$D$4,D21*CAP/$D$4,IF(CAP>=$J$4,J21*CAP/$J$4,INDEX($D21:$J21,$D$3)+$E$3*(INDEX($D21:$J21,$D$3+1)-INDEX($D21:$J21,$D$3))))
A22: 18 | B22: أخصائي غير طبيب | C22: أخصائي أطراف صناعية | D22: 0 | E22: 0 | F22: 0 | G22: 0 | H22: 2 | I22: 3 | J22: 4 | K22: =IF(RMODE="تقريب لأعلى",ROUNDUP(P22,0),ROUND(P22,0)) | M22: =L22-K22 | N22: =IF(K22=0,"",L22/K22) | O22: =IF(K22=0,"لا ينطبق",IF(L22>=K22,"مكتمل",IF(L22=0,"لا يوجد","عجز"))) | P22: =IF(CAP<=$D$4,D22*CAP/$D$4,IF(CAP>=$J$4,J22*CAP/$J$4,INDEX($D22:$J22,$D$3)+$E$3*(INDEX($D22:$J22,$D$3+1)-INDEX($D22:$J22,$D$3))))
A23: 19 | B23: أخصائي غير طبيب | C23: أخصائي أول أطراف صناعية | D23: 0 | E23: 0 | F23: 0 | G23: 0 | H23: 0 | I23: 1 | J23: 2 | K23: =IF(RMODE="تقريب لأعلى",ROUNDUP(P23,0),ROUND(P23,0)) | M23: =L23-K23 | N23: =IF(K23=0,"",L23/K23) | O23: =IF(K23=0,"لا ينطبق",IF(L23>=K23,"مكتمل",IF(L23=0,"لا يوجد","عجز"))) | P23: =IF(CAP<=$D$4,D23*CAP/$D$4,IF(CAP>=$J$4,J23*CAP/$J$4,INDEX($D23:$J23,$D$3)+$E$3*(INDEX($D23:$J23,$D$3+1)-INDEX($D23:$J23,$D$3))))
A24: 20 | B24: أخصائي غير طبيب | C24: أخصائي استشاري أطراف صناعية | D24: 0 | E24: 0 | F24: 0 | G24: 0 | H24: 0 | I24: 0 | J24: 1 | K24: =IF(RMODE="تقريب لأعلى",ROUNDUP(P24,0),ROUND(P24,0)) | M24: =L24-K24 | N24: =IF(K24=0,"",L24/K24) | O24: =IF(K24=0,"لا ينطبق",IF(L24>=K24,"مكتمل",IF(L24=0,"لا يوجد","عجز"))) | P24: =IF(CAP<=$D$4,D24*CAP/$D$4,IF(CAP>=$J$4,J24*CAP/$J$4,INDEX($D24:$J24,$D$3)+$E$3*(INDEX($D24:$J24,$D$3+1)-INDEX($D24:$J24,$D$3))))
A25: 21 | B25: أخصائي غير طبيب | C25: أخصائي معالجة نطق (تخاطب) | D25: 0 | E25: 1 | F25: 1 | G25: 2 | H25: 4 | I25: 4 | J25: 6 | K25: =IF(RMODE="تقريب لأعلى",ROUNDUP(P25,0),ROUND(P25,0)) | M25: =L25-K25 | N25: =IF(K25=0,"",L25/K25) | O25: =IF(K25=0,"لا ينطبق",IF(L25>=K25,"مكتمل",IF(L25=0,"لا يوجد","عجز"))) | P25: =IF(CAP<=$D$4,D25*CAP/$D$4,IF(CAP>=$J$4,J25*CAP/$J$4,INDEX($D25:$J25,$D$3)+$E$3*(INDEX($D25:$J25,$D$3+1)-INDEX($D25:$J25,$D$3))))
A26: 22 | B26: أخصائي غير طبيب | C26: أخصائي أول معالجة نطق (تخاطب) | D26: 0 | E26: 0 | F26: 0 | G26: 0 | H26: 2 | I26: 2 | J26: 4 | K26: =IF(RMODE="تقريب لأعلى",ROUNDUP(P26,0),ROUND(P26,0)) | M26: =L26-K26 | N26: =IF(K26=0,"",L26/K26) | O26: =IF(K26=0,"لا ينطبق",IF(L26>=K26,"مكتمل",IF(L26=0,"لا يوجد","عجز"))) | P26: =IF(CAP<=$D$4,D26*CAP/$D$4,IF(CAP>=$J$4,J26*CAP/$J$4,INDEX($D26:$J26,$D$3)+$E$3*(INDEX($D26:$J26,$D$3+1)-INDEX($D26:$J26,$D$3))))
A27: 23 | B27: أخصائي غير طبيب | C27: أخصائي استشاري معالجة نطق (تخاطب) | D27: 0 | E27: 0 | F27: 0 | G27: 0 | H27: 0 | I27: 1 | J27: 2 | K27: =IF(RMODE="تقريب لأعلى",ROUNDUP(P27,0),ROUND(P27,0)) | M27: =L27-K27 | N27: =IF(K27=0,"",L27/K27) | O27: =IF(K27=0,"لا ينطبق",IF(L27>=K27,"مكتمل",IF(L27=0,"لا يوجد","عجز"))) | P27: =IF(CAP<=$D$4,D27*CAP/$D$4,IF(CAP>=$J$4,J27*CAP/$J$4,INDEX($D27:$J27,$D$3)+$E$3*(INDEX($D27:$J27,$D$3+1)-INDEX($D27:$J27,$D$3))))
... A30: 26 | B30: أخصائي غير طبيب | C30: فسيولوجيا عصبي (أخصائي غير طبيب) | D30: 0 | E30: 0 | F30: 0 | G30: 2 | H30: 2 | I30: 3 | J30: 3 | K30: =IF(RMODE="تقريب لأعلى",ROUNDUP(P30,0),ROUND(P30,0)) | M30: =L30-K30 | N30: =IF(K30=0,"",L30/K30) | O30: =IF(K30=0,"لا ينطبق",IF(L30>=K30,"مكتمل",IF(L30=0,"لا يوجد","عجز"))) | P30: =IF(CAP<=$D$4,D30*CAP/$D$4,IF(CAP>=$J$4,J30*CAP/$J$4,INDEX($D30:$J30,$D$3)+$E$3*(INDEX($D30:$J30,$D$3+1)-INDEX($D30:$J30,$D$3))))
A31: 27 | B31: تمريض | C31: أخصائي تمريض 60% | D31: 86 | E31: 174 | F31: 270 | G31: 372 | H31: 572 | I31: 786 | J31: 1000 | K31: =IF(RMODE="تقريب لأعلى",ROUNDUP(P31,0),ROUND(P31,0)) | M31: =L31-K31 | N31: =IF(K31=0,"",L31/K31) | O31: =IF(K31=0,"لا ينطبق",IF(L31>=K31,"مكتمل",IF(L31=0,"لا يوجد","عجز"))) | P31: =IF(CAP<=$D$4,D31*CAP/$D$4,IF(CAP>=$J$4,J31*CAP/$J$4,INDEX($D31:$J31,$D$3)+$E$3*(INDEX($D31:$J31,$D$3+1)-INDEX($D31:$J31,$D$3)))) | Q31: إيضاح 30: عند أقل من 300 سرير تضاف نسبة 0.5% لمسمى أخصائي تمريض
A32: 28 | B32: تمريض | C32: أخصائي أول تمريض 10% | D32: 14 | E32: 29 | F32: 45 | G32: 62 | H32: 96 | I32: 132 | J32: 168 | K32: =IF(RMODE="تقريب لأعلى",ROUNDUP(P32,0),ROUND(P32,0)) | M32: =L32-K32 | N32: =IF(K32=0,"",L32/K32) | O32: =IF(K32=0,"لا ينطبق",IF(L32>=K32,"مكتمل",IF(L32=0,"لا يوجد","عجز"))) | P32: =IF(CAP<=$D$4,D32*CAP/$D$4,IF(CAP>=$J$4,J32*CAP/$J$4,INDEX($D32:$J32,$D$3)+$E$3*(INDEX($D32:$J32,$D$3+1)-INDEX($D32:$J32,$D$3))))
A33: 29 | B33: تمريض | C33: استشاري تمريض 0.5% | D33: 0 | E33: 0 | F33: 0 | G33: 0 | H33: 4 | I33: 6 | J33: 8 | K33: =IF(RMODE="تقريب لأعلى",ROUNDUP(P33,0),ROUND(P33,0)) | M33: =L33-K33 | N33: =IF(K33=0,"",L33/K33) | O33: =IF(K33=0,"لا ينطبق",IF(L33>=K33,"مكتمل",IF(L33=0,"لا يوجد","عجز"))) | P33: =IF(CAP<=$D$4,D33*CAP/$D$4,IF(CAP>=$J$4,J33*CAP/$J$4,INDEX($D33:$J33,$D$3)+$E$3*(INDEX($D33:$J33,$D$3+1)-INDEX($D33:$J33,$D$3)))) | Q33: إيضاح 30: تبدأ من 300 سرير وما فوق
A34: 30 | B34: قبالة | C34: أخصائي قبالة 60% | D34: 7 | E34: 15 | F34: 23 | G34: 30 | H34: 45 | I34: 59 | J34: 74 | K34: =IF(RMODE="تقريب لأعلى",ROUNDUP(P34,0),ROUND(P34,0)) | M34: =L34-K34 | N34: =IF(K34=0,"",L34/K34) | O34: =IF(K34=0,"لا ينطبق",IF(L34>=K34,"مكتمل",IF(L34=0,"لا يوجد","عجز"))) | P34: =IF(CAP<=$D$4,D34*CAP/$D$4,IF(CAP>=$J$4,J34*CAP/$J$4,INDEX($D34:$J34,$D$3)+$E$3*(INDEX($D34:$J34,$D$3+1)-INDEX($D34:$J34,$D$3)))) | Q34: إيضاح 10: معيار القابلات خاص بالمستشفيات التي تقدم خدمات النساء والولادة
A35: 31 | B35: قبالة | C35: أخصائي أول قبالة 10% | D35: 2 | E35: 3 | F35: 4 | G35: 5 | H35: 8 | I35: 10 | J35: 13 | K35: =IF(RMODE="تقريب لأعلى",ROUNDUP(P35,0),ROUND(P35,0)) | M35: =L35-K35 | N35: =IF(K35=0,"",L35/K35) | O35: =IF(K35=0,"لا ينطبق",IF(L35>=K35,"مكتمل",IF(L35=0,"لا يوجد","عجز"))) | P35: =IF(CAP<=$D$4,D35*CAP/$D$4,IF(CAP>=$J$4,J35*CAP/$J$4,INDEX($D35:$J35,$D$3)+$E$3*(INDEX($D35:$J35,$D$3+1)-INDEX($D35:$J35,$D$3)))) | Q35: إيضاح 10
A36: 32 | B36: قبالة | C36: استشاري قبالة 1% | D36: 0 | E36: 0 | F36: 0 | G36: 0 | H36: 1 | I36: 1 | J36: 1 | K36: =IF(RMODE="تقريب لأعلى",ROUNDUP(P36,0),ROUND(P36,0)) | M36: =L36-K36 | N36: =IF(K36=0,"",L36/K36) | O36: =IF(K36=0,"لا ينطبق",IF(L36>=K36,"مكتمل",IF(L36=0,"لا يوجد","عجز"))) | P36: =IF(CAP<=$D$4,D36*CAP/$D$4,IF(CAP>=$J$4,J36*CAP/$J$4,INDEX($D36:$J36,$D$3)+$E$3*(INDEX($D36:$J36,$D$3+1)-INDEX($D36:$J36,$D$3)))) | Q36: إيضاح 10
A37: 33 | B37: أخصائي غير طبيب | C37: أخصائي صحة عامة (غير طبيب) | D37: 2 | E37: 2 | F37: 2 | G37: 2 | H37: 3 | I37: 3 | J37: 3 | K37: =IF(RMODE="تقريب لأعلى",ROUNDUP(P37,0),ROUND(P37,0)) | M37: =L37-K37 | N37: =IF(K37=0,"",L37/K37) | O37: =IF(K37=0,"لا ينطبق",IF(L37>=K37,"مكتمل",IF(L37=0,"لا يوجد","عجز"))) | P37: =IF(CAP<=$D$4,D37*CAP/$D$4,IF(CAP>=$J$4,J37*CAP/$J$4,INDEX($D37:$J37,$D$3)+$E$3*(INDEX($D37:$J37,$D$3+1)-INDEX($D37:$J37,$D$3))))
A38: 34 | B38: أخصائي غير طبيب | C38: أخصائي مكافحة عدوى (غير طبيب) | D38: 3 | E38: 3 | F38: 3 | G38: 4 | H38: 5 | I38: 7 | J38: 9 | K38: =IF(RMODE="تقريب لأعلى",ROUNDUP(P38,0),ROUND(P38,0)) | M38: =L38-K38 | N38: =IF(K38=0,"",L38/K38) | O38: =IF(K38=0,"لا ينطبق",IF(L38>=K38,"مكتمل",IF(L38=0,"لا يوجد","عجز"))) | P38: =IF(CAP<=$D$4,D38*CAP/$D$4,IF(CAP>=$J$4,J38*CAP/$J$4,INDEX($D38:$J38,$D$3)+$E$3*(INDEX($D38:$J38,$D$3+1)-INDEX($D38:$J38,$D$3)))) | Q38: إيضاح 7
A39: 35 | B39: أخصائي غير طبيب | C39: أخصائي وبائيات (غير طبيب) | D39: 0 | E39: 1 | F39: 1 | G39: 2 | H39: 2 | I39: 3 | J39: 3 | K39: =IF(RMODE="تقريب لأعلى",ROUNDUP(P39,0),ROUND(P39,0)) | M39: =L39-K39 | N39: =IF(K39=0,"",L39/K39) | O39: =IF(K39=0,"لا ينطبق",IF(L39>=K39,"مكتمل",IF(L39=0,"لا يوجد","عجز"))) | P39: =IF(CAP<=$D$4,D39*CAP/$D$4,IF(CAP>=$J$4,J39*CAP/$J$4,INDEX($D39:$J39,$D$3)+$E$3*(INDEX($D39:$J39,$D$3+1)-INDEX($D39:$J39,$D$3))))
A40: 36 | B40: أخصائي غير طبيب | C40: أخصائي صحة مهنية (غير طبيب) | D40: 1 | E40: 1 | F40: 2 | G40: 2 | H40: 2 | I40: 3 | J40: 3 | K40: =IF(RMODE="تقريب لأعلى",ROUNDUP(P40,0),ROUND(P40,0)) | M40: =L40-K40 | N40: =IF(K40=0,"",L40/K40) | O40: =IF(K40=0,"لا ينطبق",IF(L40>=K40,"مكتمل",IF(L40=0,"لا يوجد","عجز"))) | P40: =IF(CAP<=$D$4,D40*CAP/$D$4,IF(CAP>=$J$4,J40*CAP/$J$4,INDEX($D40:$J40,$D$3)+$E$3*(INDEX($D40:$J40,$D$3+1)-INDEX($D40:$J40,$D$3))))
A41: 37 | B41: أخصائي غير طبيب | C41: أخصائي صحة بيئة (غير طبيب) | D41: 1 | E41: 1 | F41: 1 | G41: 1 | H41: 1 | I41: 1 | J41: 1 | K41: =IF(RMODE="تقريب لأعلى",ROUNDUP(P41,0),ROUND(P41,0)) | M41: =L41-K41 | N41: =IF(K41=0,"",L41/K41) | O41: =IF(K41=0,"لا ينطبق",IF(L41>=K41,"مكتمل",IF(L41=0,"لا يوجد","عجز"))) | P41: =IF(CAP<=$D$4,D41*CAP/$D$4,IF(CAP>=$J$4,J41*CAP/$J$4,INDEX($D41:$J41,$D$3)+$E$3*(INDEX($D41:$J41,$D$3+1)-INDEX($D41:$J41,$D$3))))
A42: 38 | B42: أخصائي غير طبيب | C42: أخصائي تخدير (غير طبيب) | D42: 5 | E42: 10 | F42: 15 | G42: 20 | H42: 30 | I42: 40 | J42: 50 | K42: =IF(RMODE="تقريب لأعلى",ROUNDUP(P42,0),ROUND(P42,0)) | M42: =L42-K42 | N42: =IF(K42=0,"",L42/K42) | O42: =IF(K42=0,"لا ينطبق",IF(L42>=K42,"مكتمل",IF(L42=0,"لا يوجد","عجز"))) | P42: =IF(CAP<=$D$4,D42*CAP/$D$4,IF(CAP>=$J$4,J42*CAP/$J$4,INDEX($D42:$J42,$D$3)+$E$3*(INDEX($D42:$J42,$D$3+1)-INDEX($D42:$J42,$D$3))))
...

Sheet عام - الفنيون
A1: عام - الفنيون
A2: الملحق (1) — الفنيون، ويشمل فني تمريض وفني قبالة (صفحة 28)
C3: معاملا الاستيفاء ◄ | D3: =IFERROR(MATCH(CAP,$D$4:$J$4,1),1) | E3: =IF(OR(CAP<=$D$4,CAP>=$J$4),0,(CAP-INDEX($D$4:$J$4,$D$3))/(INDEX($D$4:$J$4,$D$3+1)-INDEX($D$4:$J$4,$D$3)))
A4: م | B4: الفئة | C4: المسمى الوظيفي | D4: 50 | E4: 100 | F4: 150 | G4: 200 | H4: 300 | I4: 400 | J4: 500 | K4: الاحتياج للسعة المدخلة | L4: الموجود فعلياً | M4: الفجوة (+فائض / -عجز) | N4: نسبة التغطية | O4: الحالة | P4: القيمة قبل التقريب | Q4: ملاحظات
A5: 1 | B5: فني | C5: فني أشعة | D5: 6 | E5: 12 | F5: 11 | G5: 11 | H5: 12 | I5: 15 | J5: 11 | K5: =IF(RMODE="تقريب لأعلى",ROUNDUP(P5,0),ROUND(P5,0)) | M5: =L5-K5 | N5: =IF(K5=0,"",L5/K5) | O5: =IF(K5=0,"لا ينطبق",IF(L5>=K5,"مكتمل",IF(L5=0,"لا يوجد","عجز"))) | P5: =IF(CAP<=$D$4,D5*CAP/$D$4,IF(CAP>=$J$4,J5*CAP/$J$4,INDEX($D5:$J5,$D$3)+$E$3*(INDEX($D5:$J5,$D$3+1)-INDEX($D5:$J5,$D$3)))) | Q5: إيضاح 33
A6: 2 | B6: فني | C6: فني مختبر وبنك دم | D6: 9 | E6: 12 | F6: 18 | G6: 23 | H6: 27 | I6: 46 | J6: 60 | K6: =IF(RMODE="تقريب لأعلى",ROUNDUP(P6,0),ROUND(P6,0)) | M6: =L6-K6 | N6: =IF(K6=0,"",L6/K6) | O6: =IF(K6=0,"لا ينطبق",IF(L6>=K6,"مكتمل",IF(L6=0,"لا يوجد","عجز"))) | P6: =IF(CAP<=$D$4,D6*CAP/$D$4,IF(CAP>=$J$4,J6*CAP/$J$4,INDEX($D6:$J6,$D$3)+$E$3*(INDEX($D6:$J6,$D$3+1)-INDEX($D6:$J6,$D$3))))
A7: 3 | B7: فني | C7: فني علاج طبيعي | D7: 2 | E7: 4 | F7: 4 | G7: 6 | H7: 6 | I7: 8 | J7: 8 | K7: =IF(RMODE="تقريب لأعلى",ROUNDUP(P7,0),ROUND(P7,0)) | M7: =L7-K7 | N7: =IF(K7=0,"",L7/K7) | O7: =IF(K7=0,"لا ينطبق",IF(L7>=K7,"مكتمل",IF(L7=0,"لا يوجد","عجز"))) | P7: =IF(CAP<=$D$4,D7*CAP/$D$4,IF(CAP>=$J$4,J7*CAP/$J$4,INDEX($D7:$J7,$D$3)+$E$3*(INDEX($D7:$J7,$D$3+1)-INDEX($D7:$J7,$D$3))))
A8: 4 | B8: فني | C8: فني علاج وظيفي | D8: 0 | E8: 0 | F8: 0 | G8: 1 | H8: 2 | I8: 3 | J8: 4 | K8: =IF(RMODE="تقريب لأعلى",ROUNDUP(P8,0),ROUND(P8,0)) | M8: =L8-K8 | N8: =IF(K8=0,"",L8/K8) | O8: =IF(K8=0,"لا ينطبق",IF(L8>=K8,"مكتمل",IF(L8=0,"لا يوجد","عجز"))) | P8: =IF(CAP<=$D$4,D8*CAP/$D$4,IF(CAP>=$J$4,J8*CAP/$J$4,INDEX($D8:$J8,$D$3)+$E$3*(INDEX($D8:$J8,$D$3+1)-INDEX($D8:$J8,$D$3))))
A9: 5 | B9: فني | C9: فني أطراف صناعية | D9: 0 | E9: 0 | F9: 0 | G9: 0 | H9: 1 | I9: 2 | J9: 3 | K9: =IF(RMODE="تقريب لأعلى",ROUNDUP(P9,0),ROUND(P9,0)) | M9: =L9-K9 | N9: =IF(K9=0,"",L9/K9) | O9: =IF(K9=0,"لا ينطبق",IF(L9>=K9,"مكتمل",IF(L9=0,"لا يوجد","عجز"))) | P9: =IF(CAP<=$D$4,D9*CAP/$D$4,IF(CAP>=$J$4,J9*CAP/$J$4,INDEX($D9:$J9,$D$3)+$E$3*(INDEX($D9:$J9,$D$3+1)-INDEX($D9:$J9,$D$3))))
A10: 6 | B10: فني | C10: فني معالجة نطق (تخاطب) | D10: 0 | E10: 0 | F10: 0 | G10: 0 | H10: 2 | I10: 3 | J10: 4 | K10: =IF(RMODE="تقريب لأعلى",ROUNDUP(P10,0),ROUND(P10,0)) | M10: =L10-K10 | N10: =IF(K10=0,"",L10/K10) | O10: =IF(K10=0,"لا ينطبق",IF(L10>=K10,"مكتمل",IF(L10=0,"لا يوجد","عجز"))) | P10: =IF(CAP<=$D$4,D10*CAP/$D$4,IF(CAP>=$J$4,J10*CAP/$J$4,INDEX($D10:$J10,$D$3)+$E$3*(INDEX($D10:$J10,$D$3+1)-INDEX($D10:$J10,$D$3))))
A11: 7 | B11: فني | C11: فني معالجة سمع (سمعيات) | D11: 0 | E11: 0 | F11: 0 | G11: 0 | H11: 2 | I11: 3 | J11: 4 | K11: =IF(RMODE="تقريب لأعلى",ROUNDUP(P11,0),ROUND(P11,0)) | M11: =L11-K11 | N11: =IF(K11=0,"",L11/K11) | O11: =IF(K11=0,"لا ينطبق",IF(L11>=K11,"مكتمل",IF(L11=0,"لا يوجد","عجز"))) | P11: =IF(CAP<=$D$4,D11*CAP/$D$4,IF(CAP>=$J$4,J11*CAP/$J$4,INDEX($D11:$J11,$D$3)+$E$3*(INDEX($D11:$J11,$D$3+1)-INDEX($D11:$J11,$D$3))))
A12: 8 | B12: فني | C12: فني تنظير باطني | D12: 0 | E12: 0 | F12: 3 | G12: 4 | H12: 5 | I12: 6 | J12: 8 | K12: =IF(RMODE="تقريب لأعلى",ROUNDUP(P12,0),ROUND(P12,0)) | M12: =L12-K12 | N12: =IF(K12=0,"",L12/K12) | O12: =IF(K12=0,"لا ينطبق",IF(L12>=K12,"مكتمل",IF(L12=0,"لا يوجد","عجز"))) | P12: =IF(CAP<=$D$4,D12*CAP/$D$4,IF(CAP>=$J$4,J12*CAP/$J$4,INDEX($D12:$J12,$D$3)+$E$3*(INDEX($D12:$J12,$D$3+1)-INDEX($D12:$J12,$D$3))))
A13: 9 | B13: تمريض | C13: فني تمريض 30% | D13: 42 | E13: 87 | F13: 135 | G13: 186 | H13: 288 | I13: 396 | J13: 504 | K13: =IF(RMODE="تقريب لأعلى",ROUNDUP(P13,0),ROUND(P13,0)) | M13: =L13-K13 | N13: =IF(K13=0,"",L13/K13) | O13: =IF(K13=0,"لا ينطبق",IF(L13>=K13,"مكتمل",IF(L13=0,"لا يوجد","عجز"))) | P13: =IF(CAP<=$D$4,D13*CAP/$D$4,IF(CAP>=$J$4,J13*CAP/$J$4,INDEX($D13:$J13,$D$3)+$E$3*(INDEX($D13:$J13,$D$3+1)-INDEX($D13:$J13,$D$3)))) | Q13: إيضاح 11: تشغل وظائف فني بنسبة 30% حتى تقاعد الكادر الحالي ثم تحدث النسبة تدريجياً
A14: 10 | B14: قبالة | C14: فني قبالة 30% | D14: 1 | E14: 2 | F14: 3 | G14: 4 | H14: 6 | I14: 10 | J14: 12 | K14: =IF(RMODE="تقريب لأعلى",ROUNDUP(P14,0),ROUND(P14,0)) | M14: =L14-K14 | N14: =IF(K14=0,"",L14/K14) | O14: =IF(K14=0,"لا ينطبق",IF(L14>=K14,"مكتمل",IF(L14=0,"لا يوجد","عجز"))) | P14: =IF(CAP<=$D$4,D14*CAP/$D$4,IF(CAP>=$J$4,J14*CAP/$J$4,INDEX($D14:$J14,$D$3)+$E$3*(INDEX($D14:$J14,$D$3+1)-INDEX($D14:$J14,$D$3)))) | Q14: إيضاح 11
A15: 11 | B15: فني | C15: فني تخدير | D15: 4 | E15: 6 | F15: 10 | G15: 12 | H15: 15 | I15: 20 | J15: 25 | K15: =IF(RMODE="تقريب لأعلى",ROUNDUP(P15,0),ROUND(P15,0)) | M15: =L15-K15 | N15: =IF(K15=0,"",L15/K15) | O15: =IF(K15=0,"لا ينطبق",IF(L15>=K15,"مكتمل",IF(L15=0,"لا يوجد","عجز"))) | P15: =IF(CAP<=$D$4,D15*CAP/$D$4,IF(CAP>=$J$4,J15*CAP/$J$4,INDEX($D15:$J15,$D$3)+$E$3*(INDEX($D15:$J15,$D$3+1)-INDEX($D15:$J15,$D$3))))
A16: 12 | B16: فني | C16: فني عمليات | D16: 6 | E16: 10 | F16: 10 | G16: 15 | H16: 20 | I16: 25 | J16: 30 | K16: =IF(RMODE="تقريب لأعلى",ROUNDUP(P16,0),ROUND(P16,0)) | M16: =L16-K16 | N16: =IF(K16=0,"",L16/K16) | O16: =IF(K16=0,"لا ينطبق",IF(L16>=K16,"مكتمل",IF(L16=0,"لا يوجد","عجز"))) | P16: =IF(CAP<=$D$4,D16*CAP/$D$4,IF(CAP>=$J$4,J16*CAP/$J$4,INDEX($D16:$J16,$D$3)+$E$3*(INDEX($D16:$J16,$D$3+1)-INDEX($D16:$J16,$D$3))))
A17: 13 | B17: فني | C17: فني علاج تنفسي | D17: 2 | E17: 4 | F17: 6 | G17: 8 | H17: 10 | I17: 12 | J17: 18 | K17: =IF(RMODE="تقريب لأعلى",ROUNDUP(P17,0),ROUND(P17,0)) | M17: =L17-K17 | N17: =IF(K17=0,"",L17/K17) | O17: =IF(K17=0,"لا ينطبق",IF(L17>=K17,"مكتمل",IF(L17=0,"لا يوجد","عجز"))) | P17: =IF(CAP<=$D$4,D17*CAP/$D$4,IF(CAP>=$J$4,J17*CAP/$J$4,INDEX($D17:$J17,$D$3)+$E$3*(INDEX($D17:$J17,$D$3+1)-INDEX($D17:$J17,$D$3)))) | Q17: إيضاح 22: 20% فني من إجمالي العلاج التنفسي
A18: 14 | B18: فني | C18: فني جبائر | D18: 2 | E18: 2 | F18: 2 | G18: 2 | H18: 4 | I18: 4 | J18: 4 | K18: =IF(RMODE="تقريب لأعلى",ROUNDUP(P18,0),ROUND(P18,0)) | M18: =L18-K18 | N18: =IF(K18=0,"",L18/K18) | O18: =IF(K18=0,"لا ينطبق",IF(L18>=K18,"مكتمل",IF(L18=0,"لا يوجد","عجز"))) | P18: =IF(CAP<=$D$4,D18*CAP/$D$4,IF(CAP>=$J$4,J18*CAP/$J$4,INDEX($D18:$J18,$D$3)+$E$3*(INDEX($D18:$J18,$D$3+1)-INDEX($D18:$J18,$D$3))))
A19: 15 | B19: فني | C19: فني تعقيم | D19: 2 | E19: 4 | F19: 6 | G19: 8 | H19: 10 | I19: 12 | J19: 15 | K19: =IF(RMODE="تقريب لأعلى",ROUNDUP(P19,0),ROUND(P19,0)) | M19: =L19-K19 | N19: =IF(K19=0,"",L19/K19) | O19: =IF(K19=0,"لا ينطبق",IF(L19>=K19,"مكتمل",IF(L19=0,"لا يوجد","عجز"))) | P19: =IF(CAP<=$D$4,D19*CAP/$D$4,IF(CAP>=$J$4,J19*CAP/$J$4,INDEX($D19:$J19,$D$3)+$E$3*(INDEX($D19:$J19,$D$3+1)-INDEX($D19:$J19,$D$3))))
A20: 16 | B20: فني | C20: فني إسعاف وطوارئ | D20: 4 | E20: 8 | F20: 12 | G20: 15 | H20: 20 | I20: 25 | J20: 30 | K20: =IF(RMODE="تقريب لأعلى",ROUNDUP(P20,0),ROUND(P20,0)) | M20: =L20-K20 | N20: =IF(K20=0,"",L20/K20) | O20: =IF(K20=0,"لا ينطبق",IF(L20>=K20,"مكتمل",IF(L20=0,"لا يوجد","عجز"))) | P20: =IF(CAP<=$D$4,D20*CAP/$D$4,IF(CAP>=$J$4,J20*CAP/$J$4,INDEX($D20:$J20,$D$3)+$E$3*(INDEX($D20:$J20,$D$3+1)-INDEX($D20:$J20,$D$3))))
A21: 17 | B21: فني | C21: فني تقنية قلب | D21: 0 | E21: 1 | F21: 1 | G21: 2 | H21: 2 | I21: 3 | J21: 3 | K21: =IF(RMODE="تقريب لأعلى",ROUNDUP(P21,0),ROUND(P21,0)) | M21: =L21-K21 | N21: =IF(K21=0,"",L21/K21) | O21: =IF(K21=0,"لا ينطبق",IF(L21>=K21,"مكتمل",IF(L21=0,"لا يوجد","عجز"))) | P21: =IF(CAP<=$D$4,D21*CAP/$D$4,IF(CAP>=$J$4,J21*CAP/$J$4,INDEX($D21:$J21,$D$3)+$E$3*(INDEX($D21:$J21,$D$3+1)-INDEX($D21:$J21,$D$3))))
A22: 18 | B22: فني | C22: فني تخطيط المخ والأعصاب | D22: 0 | E22: 0 | F22: 2 | G22: 2 | H22: 3 | I22: 4 | J22: 4 | K22: =IF(RMODE="تقريب لأعلى",ROUNDUP(P22,0),ROUND(P22,0)) | M22: =L22-K22 | N22: =IF(K22=0,"",L22/K22) | O22: =IF(K22=0,"لا ينطبق",IF(L22>=K22,"مكتمل",IF(L22=0,"لا يوجد","عجز"))) | P22: =IF(CAP<=$D$4,D22*CAP/$D$4,IF(CAP>=$J$4,J22*CAP/$J$4,INDEX($D22:$J22,$D$3)+$E$3*(INDEX($D22:$J22,$D$3+1)-INDEX($D22:$J22,$D$3))))
A23: 19 | B23: فني | C23: فني بصريات | D23: 1 | E23: 1 | F23: 2 | G23: 3 | H23: 4 | I23: 7 | J23: 9 | K23: =IF(RMODE="تقريب لأعلى",ROUNDUP(P23,0),ROUND(P23,0)) | M23: =L23-K23 | N23: =IF(K23=0,"",L23/K23) | O23: =IF(K23=0,"لا ينطبق",IF(L23>=K23,"مكتمل",IF(L23=0,"لا يوجد","عجز"))) | P23: =IF(CAP<=$D$4,D23*CAP/$D$4,IF(CAP>=$J$4,J23*CAP/$J$4,INDEX($D23:$J23,$D$3)+$E$3*(INDEX($D23:$J23,$D$3+1)-INDEX($D23:$J23,$D$3))))
A24: 20 | B24: فني | C24: فني أجهزة طبية | D24: 2 | E24: 2 | F24: 3 | G24: 3 | H24: 3 | I24: 5 | J24: 6 | K24: =IF(RMODE="تقريب لأعلى",ROUNDUP(P24,0),ROUND(P24,0)) | M24: =L24-K24 | N24: =IF(K24=0,"",L24/K24) | O24: =IF(K24=0,"لا ينطبق",IF(L24>=K24,"مكتمل",IF(L24=0,"لا يوجد","عجز"))) | P24: =IF(CAP<=$D$4,D24*CAP/$D$4,IF(CAP>=$J$4,J24*CAP/$J$4,INDEX($D24:$J24,$D$3)+$E$3*(INDEX($D24:$J24,$D$3+1)-INDEX($D24:$J24,$D$3))))
A25: 21 | B25: فني | C25: فني أجهزة الليزر | D25: 0 | E25: 1 | F25: 1 | G25: 1 | H25: 2 | I25: 2 | J25: 2 | K25: =IF(RMODE="تقريب لأعلى",ROUNDUP(P25,0),ROUND(P25,0)) | M25: =L25-K25 | N25: =IF(K25=0,"",L25/K25) | O25: =IF(K25=0,"لا ينطبق",IF(L25>=K25,"مكتمل",IF(L25=0,"لا يوجد","عجز"))) | P25: =IF(CAP<=$D$4,D25*CAP/$D$4,IF(CAP>=$J$4,J25*CAP/$J$4,INDEX($D25:$J25,$D$3)+$E$3*(INDEX($D25:$J25,$D$3+1)-INDEX($D25:$J25,$D$3))))
A26: 22 | B26: فني | C26: سكرتير طبي | D26: 5 | E26: 15 | F26: 20 | G26: 25 | H26: 25 | I26: 30 | J26: 30 | K26: =IF(RMODE="تقريب لأعلى",ROUNDUP(P26,0),ROUND(P26,0)) | M26: =L26-K26 | N26: =IF(K26=0,"",L26/K26) | O26: =IF(K26=0,"لا ينطبق",IF(L26>=K26,"مكتمل",IF(L26=0,"لا يوجد","عجز"))) | P26: =IF(CAP<=$D$4,D26*CAP/$D$4,IF(CAP>=$J$4,J26*CAP/$J$4,INDEX($D26:$J26,$D$3)+$E$3*(INDEX($D26:$J26,$D$3+1)-INDEX($D26:$J26,$D$3))))
A27: 23 | B27: فني | C27: فني معلوماتية صحية | D27: 4 | E27: 8 | F27: 12 | G27: 12 | H27: 15 | I27: 20 | J27: 25 | K27: =IF(RMODE="تقريب لأعلى",ROUNDUP(P27,0),ROUND(P27,0)) | M27: =L27-K27 | N27: =IF(K27=0,"",L27/K27) | O27: =IF(K27=0,"لا ينطبق",IF(L27>=K27,"مكتمل",IF(L27=0,"لا يوجد","عجز"))) | P27: =IF(CAP<=$D$4,D27*CAP/$D$4,IF(CAP>=$J$4,J27*CAP/$J$4,INDEX($D27:$J27,$D$3)+$E$3*(INDEX($D27:$J27,$D$3+1)-INDEX($D27:$J27,$D$3))))
A28: 24 | B28: فني | C28: فني مراقب وبائيات | D28: 1 | E28: 1 | F28: 1 | G28: 1 | H28: 2 | I28: 2 | J28: 3 | K28: =IF(RMODE="تقريب لأعلى",ROUNDUP(P28,0),ROUND(P28,0)) | M28: =L28-K28 | N28: =IF(K28=0,"",L28/K28) | O28: =IF(K28=0,"لا ينطبق",IF(L28>=K28,"مكتمل",IF(L28=0,"لا يوجد","عجز"))) | P28: =IF(CAP<=$D$4,D28*CAP/$D$4,IF(CAP>=$J$4,J28*CAP/$J$4,INDEX($D28:$J28,$D$3)+$E$3*(INDEX($D28:$J28,$D$3+1)-INDEX($D28:$J28,$D$3))))
A29: 25 | B29: فني | C29: فني صحة عامة | D29: 1 | E29: 1 | F29: 2 | G29: 3 | H29: 4 | I29: 5 | J29: 6 | K29: =IF(RMODE="تقريب لأعلى",ROUNDUP(P29,0),ROUND(P29,0)) | M29: =L29-K29 | N29: =IF(K29=0,"",L29/K29) | O29: =IF(K29=0,"لا ينطبق",IF(L29>=K29,"مكتمل",IF(L29=0,"لا يوجد","عجز"))) | P29: =IF(CAP<=$D$4,D29*CAP/$D$4,IF(CAP>=$J$4,J29*CAP/$J$4,INDEX($D29:$J29,$D$3)+$E$3*(INDEX($D29:$J29,$D$3+1)-INDEX($D29:$J29,$D$3))))
... A34: 30 | B34: فني | C34: مساعد مدير مستشفى | D34: 0 | E34: 0 | F34: 0 | G34: 1 | H34: 2 | I34: 2 | J34: 2 | K34: =IF(RMODE="تقريب لأعلى",ROUNDUP(P34,0),ROUND(P34,0)) | M34: =L34-K34 | N34: =IF(K34=0,"",L34/K34) | O34: =IF(K34=0,"لا ينطبق",IF(L34>=K34,"مكتمل",IF(L34=0,"لا يوجد","عجز"))) | P34: =IF(CAP<=$D$4,D34*CAP/$D$4,IF(CAP>=$J$4,J34*CAP/$J$4,INDEX($D34:$J34,$D$3)+$E$3*(INDEX($D34:$J34,$D$3+1)-INDEX($D34:$J34,$D$3))))
C35: المجموع (محسوب من الجدول) | D35: =SUM(D5:D34) | E35: =SUM(E5:E34) | F35: =SUM(F5:F34) | G35: =SUM(G5:G34) | H35: =SUM(H5:H34) | I35: =SUM(I5:I34) | J35: =SUM(J5:J34) | K35: =SUM(K5:K34) | ... M35: =SUM(M5:M34) | N35: =IF(K35=0,"",L35/K35) | P35: =SUM(P5:P34)
C36: المجموع المنشور في الدليل | D36: 98 | E36: 189 | F36: 274 | G36: 359 | H36: 507 | I36: 689 | J36: 851
C37: الفرق (محسوب − منشور) | D37: =D35-D36 | E37: =E35-E36 | F37: =F35-F36 | G37: =G35-G36 | H37: =H35-H36 | I37: =I35-I36 | J37: =J35-J36

Sheet عام - الصيادلة
A1: عام - الصيادلة
A2: الملحق (1) — الصيادلة (صفحة 29)
C3: معاملا الاستيفاء ◄ | D3: =IFERROR(MATCH(CAP,$D$4:$J$4,1),1) | E3: =IF(OR(CAP<=$D$4,CAP>=$J$4),0,(CAP-INDEX($D$4:$J$4,$D$3))/(INDEX($D$4:$J$4,$D$3+1)-INDEX($D$4:$J$4,$D$3)))
A4: م | B4: الفئة | C4: المسمى الوظيفي | D4: 50 | E4: 100 | F4: 150 | G4: 200 | H4: 300 | I4: 400 | J4: 500 | K4: الاحتياج للسعة المدخلة | L4: الموجود فعلياً | M4: الفجوة (+فائض / -عجز) | N4: نسبة التغطية | O4: الحالة | P4: القيمة قبل التقريب | Q4: ملاحظات
A5: 1 | B5: صيدلي | C5: صيدلي استشاري إكلينيكي | D5: 2 | E5: 4 | F5: 6 | G5: 8 | H5: 12 | I5: 16 | J5: 20 | K5: =IF(RMODE="تقريب لأعلى",ROUNDUP(P5,0),ROUND(P5,0)) | M5: =L5-K5 | N5: =IF(K5=0,"",L5/K5) | O5: =IF(K5=0,"لا ينطبق",IF(L5>=K5,"مكتمل",IF(L5=0,"لا يوجد","عجز"))) | P5: =IF(CAP<=$D$4,D5*CAP/$D$4,IF(CAP>=$J$4,J5*CAP/$J$4,INDEX($D5:$J5,$D$3)+$E$3*(INDEX($D5:$J5,$D$3+1)-INDEX($D5:$J5,$D$3))))
A6: 2 | B6: صيدلي | C6: صيدلي أول إكلينيكي | D6: 3 | E6: 7 | F6: 11 | G6: 15 | H6: 22 | I6: 30 | J6: 37 | K6: =IF(RMODE="تقريب لأعلى",ROUNDUP(P6,0),ROUND(P6,0)) | M6: =L6-K6 | N6: =IF(K6=0,"",L6/K6) | O6: =IF(K6=0,"لا ينطبق",IF(L6>=K6,"مكتمل",IF(L6=0,"لا يوجد","عجز"))) | P6: =IF(CAP<=$D$4,D6*CAP/$D$4,IF(CAP>=$J$4,J6*CAP/$J$4,INDEX($D6:$J6,$D$3)+$E$3*(INDEX($D6:$J6,$D$3+1)-INDEX($D6:$J6,$D$3))))
A7: 3 | B7: صيدلي | C7: صيدلي إكلينيكي | D7: 0 | E7: 0 | F7: 0 | G7: 0 | H7: 0 | I7: 0 | J7: 0 | K7: =IF(RMODE="تقريب لأعلى",ROUNDUP(P7,0),ROUND(P7,0)) | M7: =L7-K7 | N7: =IF(K7=0,"",L7/K7) | O7: =IF(K7=0,"لا ينطبق",IF(L7>=K7,"مكتمل",IF(L7=0,"لا يوجد","عجز"))) | P7: =IF(CAP<=$D$4,D7*CAP/$D$4,IF(CAP>=$J$4,J7*CAP/$J$4,INDEX($D7:$J7,$D$3)+$E$3*(INDEX($D7:$J7,$D$3+1)-INDEX($D7:$J7,$D$3)))) | Q7: وارد في الدليل بقيم صفرية
A8: 4 | B8: صيدلي | C8: صيدلي استشاري | D8: 1 | E8: 1 | F8: 1 | G8: 1 | H8: 1 | I8: 1 | J8: 1 | K8: =IF(RMODE="تقريب لأعلى",ROUNDUP(P8,0),ROUND(P8,0)) | M8: =L8-K8 | N8: =IF(K8=0,"",L8/K8) | O8: =IF(K8=0,"لا ينطبق",IF(L8>=K8,"مكتمل",IF(L8=0,"لا يوجد","عجز"))) | P8: =IF(CAP<=$D$4,D8*CAP/$D$4,IF(CAP>=$J$4,J8*CAP/$J$4,INDEX($D8:$J8,$D$3)+$E$3*(INDEX($D8:$J8,$D$3+1)-INDEX($D8:$J8,$D$3))))
A9: 5 | B9: صيدلي | C9: صيدلي أول | D9: 2 | E9: 2 | F9: 2 | G9: 2 | H9: 2 | I9: 2 | J9: 2 | K9: =IF(RMODE="تقريب لأعلى",ROUNDUP(P9,0),ROUND(P9,0)) | M9: =L9-K9 | N9: =IF(K9=0,"",L9/K9) | O9: =IF(K9=0,"لا ينطبق",IF(L9>=K9,"مكتمل",IF(L9=0,"لا يوجد","عجز"))) | P9: =IF(CAP<=$D$4,D9*CAP/$D$4,IF(CAP>=$J$4,J9*CAP/$J$4,INDEX($D9:$J9,$D$3)+$E$3*(INDEX($D9:$J9,$D$3+1)-INDEX($D9:$J9,$D$3))))
A10: 6 | B10: صيدلي | C10: صيدلي | D10: 12 | E10: 25 | F10: 37 | G10: 50 | H10: 75 | I10: 100 | J10: 125 | K10: =IF(RMODE="تقريب لأعلى",ROUNDUP(P10,0),ROUND(P10,0)) | M10: =L10-K10 | N10: =IF(K10=0,"",L10/K10) | O10: =IF(K10=0,"لا ينطبق",IF(L10>=K10,"مكتمل",IF(L10=0,"لا يوجد","عجز"))) | P10: =IF(CAP<=$D$4,D10*CAP/$D$4,IF(CAP>=$J$4,J10*CAP/$J$4,INDEX($D10:$J10,$D$3)+$E$3*(INDEX($D10:$J10,$D$3+1)-INDEX($D10:$J10,$D$3))))
A11: 7 | B11: صيدلي | C11: مساعد صيدلي | D11: 15 | E11: 30 | F11: 45 | G11: 60 | H11: 90 | I11: 120 | J11: 150 | K11: =IF(RMODE="تقريب لأعلى",ROUNDUP(P11,0),ROUND(P11,0)) | M11: =L11-K11 | N11: =IF(K11=0,"",L11/K11) | O11: =IF(K11=0,"لا ينطبق",IF(L11>=K11,"مكتمل",IF(L11=0,"لا يوجد","عجز"))) | P11: =IF(CAP<=$D$4,D11*CAP/$D$4,IF(CAP>=$J$4,J11*CAP/$J$4,INDEX($D11:$J11,$D$3)+$E$3*(INDEX($D11:$J11,$D$3+1)-INDEX($D11:$J11,$D$3))))
C12: المجموع (محسوب من الجدول) | D12: =SUM(D5:D11) | E12: =SUM(E5:E11) | F12: =SUM(F5:F11) | G12: =SUM(G5:G11) | H12: =SUM(H5:H11) | I12: =SUM(I5:I11) | J12: =SUM(J5:J11) | K12: =SUM(K5:K11) | ... M12: =SUM(M5:M11) | N12: =IF(K12=0,"",L12/K12) | P12: =SUM(P5:P11)
C13: المجموع المنشور في الدليل | D13: 35 | E13: 69 | F13: 102 | G13: 136 | H13: 202 | I13: 269 | J13: 335
C14: الفرق (محسوب − منشور) | D14: =D12-D13 | E14: =E12-E13 | F14: =F12-F13 | G14: =G12-G13 | H14: =H12-H13 | I14: =I12-I13 | J14: =J12-J13

Sheet عام - المساعد الصحي
A1: عام - المساعد الصحي
A2: الملحق (1) — المساعد الصحي (صفحة 29)
C3: معاملا الاستيفاء ◄ | D3: =IFERROR(MATCH(CAP,$D$4:$J$4,1),1) | E3: =IF(OR(CAP<=$D$4,CAP>=$J$4),0,(CAP-INDEX($D$4:$J$4,$D$3))/(INDEX($D$4:$J$4,$D$3+1)-INDEX($D$4:$J$4,$D$3)))
A4: م | B4: الفئة | C4: المسمى الوظيفي | D4: 50 | E4: 100 | F4: 150 | G4: 200 | H4: 300 | I4: 400 | J4: 500 | K4: الاحتياج للسعة المدخلة | L4: الموجود فعلياً | M4: الفجوة (+فائض / -عجز) | N4: نسبة التغطية | O4: الحالة | P4: القيمة قبل التقريب | Q4: ملاحظات
A5: 1 | B5: مساعد صحي | C5: مساعد صحي / فني رعاية مرضى | D5: 18 | E5: 36 | F5: 56 | G5: 78 | H5: 120 | I5: 165 | J5: 210 | K5: =IF(RMODE="تقريب لأعلى",ROUNDUP(P5,0),ROUND(P5,0)) | M5: =L5-K5 | N5: =IF(K5=0,"",L5/K5) | O5: =IF(K5=0,"لا ينطبق",IF(L5>=K5,"مكتمل",IF(L5=0,"لا يوجد","عجز"))) | P5: =IF(CAP<=$D$4,D5*CAP/$D$4,IF(CAP>=$J$4,J5*CAP/$J$4,INDEX($D5:$J5,$D$3)+$E$3*(INDEX($D5:$J5,$D$3+1)-INDEX($D5:$J5,$D$3)))) | Q5: إيضاح 40: أضيف فني رعاية مرضى (مساعدة ممرضة سابقاً) بناءً على معايير الهيئة السعودية للتخصصات الصحية
A6: 2 | B6: مساعد صحي | C6: مساعد تمريض رجال | D6: 3 | E6: 4 | F6: 6 | G6: 8 | H6: 10 | I6: 10 | J6: 15 | K6: =IF(RMODE="تقريب لأعلى",ROUNDUP(P6,0),ROUND(P6,0)) | M6: =L6-K6 | N6: =IF(K6=0,"",L6/K6) | O6: =IF(K6=0,"لا ينطبق",IF(L6>=K6,"مكتمل",IF(L6=0,"لا يوجد","عجز"))) | P6: =IF(CAP<=$D$4,D6*CAP/$D$4,IF(CAP>=$J$4,J6*CAP/$J$4,INDEX($D6:$J6,$D$3)+$E$3*(INDEX($D6:$J6,$D$3+1)-INDEX($D6:$J6,$D$3))))
A7: 3 | B7: مساعد صحي | C7: مسعف | D7: 6 | E7: 10 | F7: 10 | G7: 13 | H7: 14 | I7: 17 | J7: 20 | K7: =IF(RMODE="تقريب لأعلى",ROUNDUP(P7,0),ROUND(P7,0)) | M7: =L7-K7 | N7: =IF(K7=0,"",L7/K7) | O7: =IF(K7=0,"لا ينطبق",IF(L7>=K7,"مكتمل",IF(L7=0,"لا يوجد","عجز"))) | P7: =IF(CAP<=$D$4,D7*CAP/$D$4,IF(CAP>=$J$4,J7*CAP/$J$4,INDEX($D7:$J7,$D$3)+$E$3*(INDEX($D7:$J7,$D$3+1)-INDEX($D7:$J7,$D$3))))
A8: 4 | B8: مساعد صحي | C8: مسعف (سائق) | D8: 6 | E8: 8 | F8: 8 | G8: 11 | H8: 11 | I8: 15 | J8: 18 | K8: =IF(RMODE="تقريب لأعلى",ROUNDUP(P8,0),ROUND(P8,0)) | M8: =L8-K8 | N8: =IF(K8=0,"",L8/K8) | O8: =IF(K8=0,"لا ينطبق",IF(L8>=K8,"مكتمل",IF(L8=0,"لا يوجد","عجز"))) | P8: =IF(CAP<=$D$4,D8*CAP/$D$4,IF(CAP>=$J$4,J8*CAP/$J$4,INDEX($D8:$J8,$D$3)+$E$3*(INDEX($D8:$J8,$D$3+1)-INDEX($D8:$J8,$D$3))))
A9: 5 | B9: مساعد صحي | C9: مساعد صحي سحب دم | D9: 2 | E9: 6 | F9: 6 | G9: 8 | H9: 10 | I9: 12 | J9: 12 | K9: =IF(RMODE="تقريب لأعلى",ROUNDUP(P9,0),ROUND(P9,0)) | M9: =L9-K9 | N9: =IF(K9=0,"",L9/K9) | O9: =IF(K9=0,"لا ينطبق",IF(L9>=K9,"مكتمل",IF(L9=0,"لا يوجد","عجز"))) | P9: =IF(CAP<=$D$4,D9*CAP/$D$4,IF(CAP>=$J$4,J9*CAP/$J$4,INDEX($D9:$J9,$D$3)+$E$3*(INDEX($D9:$J9,$D$3+1)-INDEX($D9:$J9,$D$3))))
C10: المجموع (محسوب من الجدول) | D10: =SUM(D5:D9) | E10: =SUM(E5:E9) | F10: =SUM(F5:F9) | G10: =SUM(G5:G9) | H10: =SUM(H5:H9) | I10: =SUM(I5:I9) | J10: =SUM(J5:J9) | K10: =SUM(K5:K9) | ... M10: =SUM(M5:M9) | N10: =IF(K10=0,"",L10/K10) | P10: =SUM(P5:P9)
C11: المجموع المنشور في الدليل | D11: 35 | E11: 64 | F11: 86 | G11: 118 | H11: 165 | I11: 219 | J11: 275
C12: الفرق (محسوب − منشور) | D12: =D10-D11 | E12: =E10-E11 | F12: =F10-F11 | G12: =G10-G11 | H12: =H10-H11 | I12: =I10-I11 | J12: =J10-J11

Sheet عام - الإداريون
A1: عام - الإداريون
A2: الملحق (1) — الإداريون (صفحات 29-30)
C3: معاملا الاستيفاء ◄ | D3: =IFERROR(MATCH(CAP,$D$4:$J$4,1),1) | E3: =IF(OR(CAP<=$D$4,CAP>=$J$4),0,(CAP-INDEX($D$4:$J$4,$D$3))/(INDEX($D$4:$J$4,$D$3+1)-INDEX($D$4:$J$4,$D$3)))
A4: م | B4: الفئة | C4: المسمى الوظيفي | D4: 50 | E4: 100 | F4: 150 | G4: 200 | H4: 300 | I4: 400 | J4: 500 | K4: الاحتياج للسعة المدخلة | L4: الموجود فعلياً | M4: الفجوة (+فائض / -عجز) | N4: نسبة التغطية | O4: الحالة | P4: القيمة قبل التقريب | Q4: ملاحظات
A5: 1 | B5: إداري | C5: سكرتير | D5: 2 | E5: 4 | F5: 4 | G5: 8 | H5: 8 | I5: 12 | J5: 14 | K5: =IF(RMODE="تقريب لأعلى",ROUNDUP(P5,0),ROUND(P5,0)) | M5: =L5-K5 | N5: =IF(K5=0,"",L5/K5) | O5: =IF(K5=0,"لا ينطبق",IF(L5>=K5,"مكتمل",IF(L5=0,"لا يوجد","عجز"))) | P5: =IF(CAP<=$D$4,D5*CAP/$D$4,IF(CAP>=$J$4,J5*CAP/$J$4,INDEX($D5:$J5,$D$3)+$E$3*(INDEX($D5:$J5,$D$3+1)-INDEX($D5:$J5,$D$3))))
